Workbook
Name beta_observed: #REF!
Name beta_unlev_comps: #REF!
Name conversionfactor: '[10]E&P'!$D$6
Name convfactor: #REF!
Name costdebtfirm: #REF!
Name costequity: #REF!
Name days_per_year: #REF!
Name debt: #REF!
Name debt_weight: #REF!
Name market_equity: #REF!
Name relevered_beta: #REF!
Name risk_free_rate: #REF!
Name risk_premium: #REF!
Name stubyear: #REF!
Name totalcap: #REF!
Name wacc: #REF!

Sheet Transaction Summary
B2: Transaction Summary
B4: Sources & Uses
D5: CLOSE | H5: HOLD
D6: Total | E6: % of Total | F6: Per Unit | H6: Total | I6: % of Total | J6: Per Unit
B7: Uses
B8: Acquisition Costs | D8: =Model!E169 -> 5700000 | E8: =D8/D$14 -> 0.81015393 | F8: =D8/$J$25 -> 19000 | H8: =Model!F169 -> 5700000 | I8: =H8/H$14 -> 0.096904661 | J8: =H8/$J$25 -> 19000
B9: Soft Costs | D9: =Model!E170 -> 0 | E9: =D9/D$14 -> 0 | F9: =D9/$J$25 -> 0 | H9: =Model!F170 -> 5460000 | I9: =H9/H$14 -> 0.092824465 | J9: =H9/$J$25 -> 18200
B10: Hard Costs | D10: =Model!E171 -> 0 | E10: =D10/D$14 -> 0 | F10: =D10/$J$25 -> 0 | H10: =Model!F171 -> 44500000 | I10: =H10/H$14 -> 0.75653639 | J10: =H10/$J$25 -> 148333.33
B11: Other Development Costs | D11: =Model!E172 -> 0 | E11: =D11/D$14 -> 0 | F11: =D11/$J$25 -> 0 | H11: =Model!F172 -> 1750000 | I11: =H11/H$14 -> 0.029751431 | J11: =H11/$J$25 -> 5833.3333
B12: Financing Costs | D12: =Model!E173 -> 1335700 | E12: =D12/D$14 -> 0.18984607 | F12: =D12/$J$25 -> 4452.3333 | H12: =Model!F173 -> 1335700 | I12: =H12/H$14 -> 0.022707992 | J12: =H12/$J$25 -> 4452.3333
B13: Capital Reserves | D13: =Model!E174 -> 0 | E13: =D13/D$14 -> 0 | F13: =D13/$J$25 -> 0 | H13: =Model!F174 -> 75000 | I13: =H13/H$14 -> 0.0012750613 | J13: =H13/$J$25 -> 250
B14: Total Uses | D14: =SUM(D8:D13) -> 7035700 | E14: =SUM(E8:E13) -> 1 | F14: =SUM(F8:F13) -> 23452.333 | H14: =SUM(H8:H13) -> 58820700 | I14: =SUM(I8:I13) -> 1 | J14: =SUM(J8:J13) -> 196069
B16: Sources
B17: Equity | D17: =Model!E178 -> 6100000 | E17: =D17/D$20 -> 0.86700684 | F17: =D17/$J$25 -> 20333.333 | H17: =Model!F178 -> 18749450 | I17: =H17/H$20 -> 0.31875598 | J17: =H17/$J$25 -> 62498.167
B18: Debt | D18: =Model!E179 -> 0 | E18: =D18/D$20 -> 0 | F18: =D18/$J$25 -> 0 | H18: =Model!F179 -> 40000000 | I18: =H18/H$20 -> 0.68003271 | J18: =H18/$J$25 -> 133333.33
B19: Operating Cashflow | D19: =Model!E180 -> 935700 | E19: =D19/D$20 -> 0.13299316 | F19: =D19/$J$25 -> 3119 | H19: =Model!F180 -> 71250 | I19: =H19/H$20 -> 0.0012113083 | J19: =H19/$J$25 -> 237.5
B20: Total Sources | D20: =SUM(D17:D19) -> 7035700 | E20: =SUM(E17:E19) -> 1 | F20: =SUM(F17:F19) -> 23452.333 | H20: =SUM(H17:H19) -> 58820700 | I20: =SUM(I17:I19) -> 1 | J20: =SUM(J17:J19) -> 196069
B22: Returns Summary | H22: Deal Summary
C23: Peak Equity | D23: IRR | E23: Profit | F23: Multiple | H23: Location | J23: ='Inputs & Drivers'!E7 -> Boston, MA
B24: Unlevered Project | C24: {=TRANSPOSE(Model!C100:C103)} -> 57090929 | D24: 0.16394511 | E24: 19459558 | F24: 1.340852 | H24: Vintage | J24: ='Inputs & Drivers'!E9 -> 2015
B25: Levered Project | C25: {=TRANSPOSE(Model!C162:C165)} -> 18749450 | D25: 0.27464951 | E25: 15915270 | F25: 1.8488393 | H25: Total Units | J25: ='Inputs & Drivers'!E8 -> 300
B26: LP | C26: {=TRANSPOSE(Model!C263:C266)} -> 16874505 | D26: 0.22744136 | E26: 11449567 | F26: 1.6785127 | H26: Hold Period | J26: ='Inputs & Drivers'!E13 -> 36
B27: GP | C27: {=TRANSPOSE(Model!C277:C280)} -> 1874945 | D27: 0.60943713 | E27: 4465703 | F27: 3.3817781 | H27: Rentable SF | J27: ='Inputs & Drivers'!F34*'Inputs & Drivers'!C34 -> 289000
B28: GP Project | C28: {=TRANSPOSE(Model!C270:C273)} -> 1874945 | D28: 0.22744136 | E28: 1272174.1 | F28: 1.6785127 | H28: Avg Unit Size | J28: ='Inputs & Drivers'!F34 -> 963.33333
B29: GP Promote | C29: n/a | D29: n/a | E29: =E27-E28 -> 3193528.9 | F29: n/a | H29: Occupancy | J29: ='Inputs & Drivers'!E49 -> 0.93
B31: NOI Summary | H31: Debt Summary
C32: NOI | D32: Growth | E32: NOI YoC | F32: Delta to Exit Cap | H32: Loan Proceeds | J32: ='Inputs & Drivers'!J16 -> 40000000
B33: 1 | C33: {=TRANSPOSE(Model!EM80:ER80)} -> 0 | E33: =C33/$H$20 -> 0 | F33: =E33-$D$42 -> -0.055 | H33: Leverage (Close / Life) | J33: =TEXT(D18/D20,"0%")&" / "&TEXT(H18/H20,"0%") -> 0% / 68%
B34: 2 | C34: 728720.74 | D34: =IFERROR(C34/C33-1,0) -> 0 | E34: =C34/$H$20 -> 0.012388848 | F34: =E34-$D$42 -> -0.042611152 | H34: Rate | J34: ='Inputs & Drivers'!J19 -> 0.051562
B35: 3 | C35: 3639516.9 | D35: =IFERROR(C35/C34-1,0) -> 3.9943919 | E35: =C35/$H$20 -> 0.061874764 | F35: =E35-$D$42 -> 0.0068747641 | H35: Fees | J35: ='Inputs & Drivers'!J24 -> 0.01
B36: 4 | C36: 4032017.8 | D36: =IFERROR(C36/C35-1,0) -> 0.10784421 | E36: =C36/$H$20 -> 0.068547599 | F36: =E36-$D$42 -> 0.013547599 | H36: IO Period | J36: ='Inputs & Drivers'!J21 -> 36
B37: 5 | C37: 4155645.8 | D37: =IFERROR(C37/C36-1,0) -> 0.030661583 | E37: =C37/$H$20 -> 0.070649377 | F37: =E37-$D$42 -> 0.015649377 | H37: Maturity | J37: ='Inputs & Drivers'!J15 -> 45291
B38: 6 | C38: 4283054.1 | D38: =IFERROR(C38/C37-1,0) -> 0.030659086 | E38: =C38/$H$20 -> 0.072815422 | F38: =E38-$D$42 -> 0.017815422
H39: Joint Venture Summary
B40: Exit Summary | H40: GP Equity | J40: ='Inputs & Drivers'!H5 -> 0.1
C41: Fwd NOI | D41: Exit Cap | E41: Total $ | F41: Per Unit | H41: Pref | J41: ='Inputs & Drivers'!I7 -> 0.1
B42: Sale Proceeds | C42: =SUMIF(Model!$H$6:$EJ$6,'Inputs & Drivers'!$E$14,Model!$H$81:$EJ$81) -> 4032017.8 | D42: ='Inputs & Drivers'!E16 -> 0.055 | E42: =C42/D42 -> 73309414 | F42: =E42/$J$25 -> 244364.71 | H42: Hurdle #2 | J42: =TEXT('Inputs & Drivers'!H8,"0.0%")&" after a "&TEXT('Inputs & Drivers'!I7,"0.0%") -> 20.0% after a 10.0%
B43: Less: Sale Costs | E43: =-'Inputs & Drivers'!E15*E42 -> -733094.14 | H43: Hurdle #3 | J43: =TEXT('Inputs & Drivers'!H9,"0.0%")&" after a "&TEXT('Inputs & Drivers'!I8,"0.0%") -> 30.0% after a 15.0%
B44: Net Sale Proceeds | E44: =SUM(E42:E43) -> 72576320 | H44: Hurdle #4 | J44: =TEXT('Inputs & Drivers'!H10,"0.0%")&" after a "&TEXT('Inputs & Drivers'!I9,"0.0%") -> 40.0% after a 20.0%
B45: Less: Outstanding Debt | D45: Value | E45: =SUMIF(Model!$H$6:$EJ$6,'Inputs & Drivers'!$E$14,Model!H154:EJ154) -> -40000000
...

Sheet Inputs & Drivers
B2: Inputs
B4: Property Overview | G4: Joint Venture Assumptions | L4: Checks | P4: LIBOR Index | S4: Amortization Table | AA4: Sensitivity Tables
B5: Name | E5: Multifamily Property | G5: GP Equity | H5: 0.1 | L5: S&U - Hold | N5: =Model!F183 -> Ok
B6: Type | E6: Development | H6: Promote | I6: Pref | J6: Splits | L6: S&U - Close | N6: =Model!E183 -> Ok | P6: Date | Q6: LIBOR | S6: PMT | T6: =PMT($J$23/12,$J$22*12,-$J$16) -> 214728.65 | AA6: Exit Cap | AB6: Annual Rent Growth - Steady State
B7: Location | E7: Boston, MA | G7: Hurdle #1 | H7: n/a | I7: 0.1 | J7: =H5 -> 0.1 | L7: S&U - Monthly | N7: =IF(SUM(Model!H183:EJ183)=0,"Ok","Check") -> Ok | P7: 44196 | Q7: 0.016562 | AA7: =IF(ISERROR(CONCATENATE(TEXT($N$21,"0.0%"),", ",TEXT($N$22/1000000,"$0.0"),"M, ",TEXT($N$23,"0.0x"))),0,CONCATENATE(TEXT($N$21,"0.0%"),", ",TEXT($N$22/1000000,"$0.0"),"M, ",TEXT($N$23,"0.0x"))) -> 27.5%, $15.9M, 1.8x | AB7: =AC7-0.25% -> 0.025 | AC7: =AD7-0.25% -> 0.0275 | AD7: 0.03 | AE7: =AD7+0.25% -> 0.0325 | AF7: =AE7+0.25% -> 0.035
B8: Units | E8: =C34 -> 300 | G8: Hurdle #2 | H8: 0.2 | I8: 0.15 | J8: =$H$5+(H8*(1-$H$5)) -> 0.28 | L8: S&U - Summary | N8: =IF(ROUND('Transaction Summary'!D14+'Transaction Summary'!H14-'Transaction Summary'!D20-'Transaction Summary'!H20,0)=0,"Ok","Check") -> Ok | P8: 44227 | Q8: 0.0162663 | S8: Date | T8: Period | U8: Payment | V8: Beg. Balance | W8: Principal | X8: Interest | Y8: End Balance | AA8: =AA9-0.25% -> 0.045
B9: Year Built | E9: 2015 | G9: Hurdle #3 | H9: 0.3 | I9: 0.2 | J9: =$H$5+(H9*(1-$H$5)) -> 0.37 | L9: Summary NOI | N9: =IF(SUM('Transaction Summary'!F71:J71)=SUM(Model!EM80:EQ80),"Ok","Check") -> Ok | P9: 44255 | Q9: 0.015964 | S9: =J13 -> 44196 | T9: 0 | Y9: =J16 -> 40000000 | AA9: =AA10-0.25% -> 0.0475
G10: Hurdle #4 | H10: 0.4 | I10: 5 | J10: =$H$5+(H10*(1-$H$5)) -> 0.46 | L10: Debt Paydown | N10: =IF(SUM(Model!H152:EJ152,Model!H153:EJ154)=0,"Ok","Check") -> Ok | P10: 44286 | Q10: 0.0156102 | S10: =EOMONTH(S9,1) -> 44227 | T10: =T9+1 -> 1 | U10: =IF(T10<=$J$21,$X10,$T$6) -> 177602.44 | V10: =Y9 -> 40000000 | W10: =U10-X10 -> 0 | X10: =$J$19/$I$13*($S10-$S9)*V10 -> 177602.44 | Y10: =V10-W10 -> 40000000 | AA10: =AA11-0.25% -> 0.05
B11: Investment Overview | L11: Deal Profit | N11: =IF(ROUND(Model!C164-Model!C265-Model!C279,-1)=0,"Ok","Check") -> Ok | P11: 44316 | Q11: 0.0152492 | S11: =EOMONTH(S10,1) -> 44255 | T11: =T10+1 -> 2 | U11: =IF(T11<=$J$21,$X11,$T$6) -> 160415.11 | V11: =Y10 -> 40000000 | W11: =U11-X11 -> 0 | X11: =$J$19/$I$13*($S11-$S10)*V11 -> 160415.11 | Y11: =V11-W11 -> 40000000 | AA11: =AA12-0.25% -> 0.0525
B12: Acquisition Date | E12: 44196 | G12: Financing Assumptions | L12: Remaining CF | N12: =IF(SUM(Model!H258:EJ258)=0,"Ok","Check") -> Ok | P12: 44347 | Q12: 0.0149364 | S12: =EOMONTH(S11,1) -> 44286 | T12: =T11+1 -> 3 | U12: =IF(T12<=$J$21,$X12,$T$6) -> 177602.44 | V12: =Y11 -> 40000000 | W12: =U12-X12 -> 0 | X12: =$J$19/$I$13*($S12-$S11)*V12 -> 177602.44 | Y12: =V12-W12 -> 40000000 | AA12: 0.055
B13: Hold Period | E13: 36 | G13: Start Date | H13: Floating | I13: 360 | J13: =E12 -> 44196 | L13: IRR | N13: =IF(AND(Model!C261=Model!C268,Model!C261<=Model!C275),"Ok","Check") -> Ok | P13: 44377 | Q13: 0.0145569 | S13: =EOMONTH(S12,1) -> 44316 | T13: =T12+1 -> 4 | U13: =IF(T13<=$J$21,$X13,$T$6) -> 171873.33 | V13: =Y12 -> 40000000 | W13: =U13-X13 -> 0 | X13: =$J$19/$I$13*($S13-$S12)*V13 -> 171873.33 | Y13: =V13-W13 -> 40000000 | AA13: =AA12+0.25% -> 0.0575
B14: Exit Date | E14: =EOMONTH(E12,E13) -> 45291 | G14: Term | J14: =E13 -> 36 | L14: YoC | N14: =IF(ROUND(Model!ER83,-1)=ROUND('Transaction Summary'!E38,-1),"Ok","Check") -> Ok | P14: 44408 | Q14: 0.0141933 | S14: =EOMONTH(S13,1) -> 44347 | T14: =T13+1 -> 5 | U14: =IF(T14<=$J$21,$X14,$T$6) -> 177602.44 | V14: =Y13 -> 40000000 | W14: =U14-X14 -> 0 | X14: =$J$19/$I$13*($S14-$S13)*V14 -> 177602.44 | Y14: =V14-W14 -> 40000000 | AA14: =AA13+0.25% -> 0.06
B15: Exit Closing Costs | E15: 0.01 | G15: Maturity Date | J15: =EOMONTH(J13,J14) -> 45291 | L15: Total Profit | N15: =IF(AND(ROUND('Transaction Summary'!E49,0)=ROUND(Model!F159,0),ROUND(Model!F159,0)=ROUND(Model!C164,0)),"Ok","Check") -> Ok | P15: 44439 | Q15: 0.0138616 | S15: =EOMONTH(S14,1) -> 44377 | T15: =T14+1 -> 6 | U15: =IF(T15<=$J$21,$X15,$T$6) -> 171873.33 | V15: =Y14 -> 40000000 | W15: =U15-X15 -> 0 | X15: =$J$19/$I$13*($S15-$S14)*V15 -> 171873.33 | Y15: =V15-W15 -> 40000000 | AA15: =AA14+0.25% -> 0.0625
B16: Exit Cap Rate | E16: 0.055 | G16: Loan Amount | J16: 40000000 | L16: Debt Draw | N16: =IF(J16='Transaction Summary'!H18,"Ok","Check") -> Ok | P16: 44469 | Q16: 0.0135342 | S16: =EOMONTH(S15,1) -> 44408 | T16: =T15+1 -> 7 | U16: =IF(T16<=$J$21,$X16,$T$6) -> 177602.44 | V16: =Y15 -> 40000000 | W16: =U16-X16 -> 0 | X16: =$J$19/$I$13*($S16-$S15)*V16 -> 177602.44 | Y16: =V16-W16 -> 40000000 | AA16: =AA15+0.25% -> 0.065
B17: Sale Price | D17: =E17/$E$8 -> 244364.71 | E17: =SUM(Model!H94:EJ94) -> 73309414 | G17: Loan-to-Cost | J17: =J16/E18 -> 0.6809009 | L17: Dev. Budget | N17: =IF(-SUM(Model!F90:F93,Model!F131,Model!F139,Model!F150)='Development Budget'!E34,"Ok","Check") -> Ok | P17: 44500 | Q17: 0.0132701 | S17: =EOMONTH(S16,1) -> 44439 | T17: =T16+1 -> 8 | U17: =IF(T17<=$J$21,$X17,$T$6) -> 177602.44 | V17: =Y16 -> 40000000 | W17: =U17-X17 -> 0 | X17: =$J$19/$I$13*($S17-$S16)*V17 -> 177602.44 | Y17: =V17-W17 -> 40000000
B18: Total Cost | D18: =E18/$E$8 -> 195819 | E18: ='Development Budget'!E34 -> 58745700 | G18: Interest Rate Spread | I18: L+ | J18: 350 | L18: Reserves | N18: =IF(AND(ROUND(Model!F127+Model!F131,0)=0,ROUND(Model!F135+Model!F139,0)=0),"Ok","Check") -> Ok | P18: 44530 | Q18: 0.0130594 | S18: =EOMONTH(S17,1) -> 44469 | T18: =T17+1 -> 9 | U18: =IF(T18<=$J$21,$X18,$T$6) -> 171873.33 | V18: =Y17 -> 40000000 | W18: =U18-X18 -> 0 | X18: =$J$19/$I$13*($S18-$S17)*V18 -> 171873.33 | Y18: =V18-W18 -> 40000000 | AA18: Exit Cap | AB18: Hold Period
B19: Untrended YoC | E19: =(E63-J60)/E18 -> 0.056721392 | G19: All-in Rate | J19: =Q7+J18/10000 -> 0.051562 | P19: 44561 | Q19: 0.0128912 | S19: =EOMONTH(S18,1) -> 44500 | T19: =T18+1 -> 10 | U19: =IF(T19<=$J$21,$X19,$T$6) -> 177602.44 | V19: =Y18 -> 40000000 | W19: =U19-X19 -> 0 | X19: =$J$19/$I$13*($S19-$S18)*V19 -> 177602.44 | Y19: =V19-W19 -> 40000000 | AA19: =IF(ISERROR(CONCATENATE(TEXT($N$21,"0.0%"),", ",TEXT($N$22/1000000,"$0.0"),"M, ",TEXT($N$23,"0.0x"))),0,CONCATENATE(TEXT($N$21,"0.0%"),", ",TEXT($N$22/1000000,"$0.0"),"M, ",TEXT($N$23,"0.0x"))) -> 27.5%, $15.9M, 1.8x | AB19: =AC19-12 -> 36 | AC19: =AD19-12 -> 48 | AD19: 60 | AE19: =AD19+12 -> 72 | AF19: =AE19+12 -> 84
B20: Stabilized YoC | E20: =SUMIF(Model!$H$5:$EJ$5,'Inputs & Drivers'!$J$42+1,Model!$H$83:$EJ$83) -> 0.06677428 | G20: Fixed Rate | J20: 0.05 | L20: Project Returns | P20: 44592 | Q20: 0.0127664 | S20: =EOMONTH(S19,1) -> 44530 | T20: =T19+1 -> 11 | U20: =IF(T20<=$J$21,$X20,$T$6) -> 171873.33 | V20: =Y19 -> 40000000 | W20: =U20-X20 -> 0 | X20: =$J$19/$I$13*($S20-$S19)*V20 -> 171873.33 | Y20: =V20-W20 -> 40000000 | AA20: =AA21-0.25% -> 0.045
G21: Interest Only Period | J21: 36 | L21: IRR | N21: =Model!C163 -> 0.27464951 | P21: 44620 | Q21: 0.0126461 | S21: =EOMONTH(S20,1) -> 44561 | T21: =T20+1 -> 12 | U21: =IF(T21<=$J$21,$X21,$T$6) -> 177602.44 | V21: =Y20 -> 40000000 | W21: =U21-X21 -> 0 | X21: =$J$19/$I$13*($S21-$S20)*V21 -> 177602.44 | Y21: =V21-W21 -> 40000000 | AA21: =AA22-0.25% -> 0.0475
G22: Amortization Period | J22: 30 | L22: Profit | N22: =Model!C164 -> 15915270 | P22: 44651 | Q22: 0.0125157 | S22: =EOMONTH(S21,1) -> 44592 | T22: =T21+1 -> 13 | U22: =IF(T22<=$J$21,$X22,$T$6) -> 177602.44 | V22: =Y21 -> 40000000 | W22: =U22-X22 -> 0 | X22: =$J$19/$I$13*($S22-$S21)*V22 -> 177602.44 | Y22: =V22-W22 -> 40000000 | AA22: =AA23-0.25% -> 0.05
G23: Amortization Rate | J23: 0.05 | L23: Multiple | N23: =Model!C165 -> 1.8488393 | P23: 44681 | Q23: 0.0123878 | S23: =EOMONTH(S22,1) -> 44620 | T23: =T22+1 -> 14 | U23: =IF(T23<=$J$21,$X23,$T$6) -> 160415.11 | V23: =Y22 -> 40000000 | W23: =U23-X23 -> 0 | X23: =$J$19/$I$13*($S23-$S22)*V23 -> 160415.11 | Y23: =V23-W23 -> 40000000 | AA23: =AA24-0.25% -> 0.0525
G24: Origination Fee | J24: 0.01 | P24: 44712 | Q24: 0.0122618 | S24: =EOMONTH(S23,1) -> 44651 | T24: =T23+1 -> 15 | U24: =IF(T24<=$J$21,$X24,$T$6) -> 177602.44 | V24: =Y23 -> 40000000 | W24: =U24-X24 -> 0 | X24: =$J$19/$I$13*($S24-$S23)*V24 -> 177602.44 | Y24: =V24-W24 -> 40000000 | AA24: 0.055
G25: Interest Reserve | J25: =Model!F127 -> 907885.1 | L25: LP Returns | P25: 44742 | Q25: 0.0121419 | S25: =EOMONTH(S24,1) -> 44681 | T25: =T24+1 -> 16 | U25: =IF(T25<=$J$21,$X25,$T$6) -> 171873.33 | V25: =Y24 -> 40000000 | W25: =U25-X25 -> 0 | X25: =$J$19/$I$13*($S25-$S24)*V25 -> 171873.33 | Y25: =V25-W25 -> 40000000 | AA25: =AA24+0.25% -> 0.0575
G26: Operating Reserve | J26: =Model!F135 -> 27814.901 | L26: IRR | N26: =Model!C264 -> 0.22744136 | P26: 44773 | Q26: 0.0120598 | S26: =EOMONTH(S25,1) -> 44712 | T26: =T25+1 -> 17 | U26: =IF(T26<=$J$21,$X26,$T$6) -> 177602.44 | V26: =Y25 -> 40000000 | W26: =U26-X26 -> 0 | X26: =$J$19/$I$13*($S26-$S25)*V26 -> 177602.44 | Y26: =V26-W26 -> 40000000 | AA26: =AA25+0.25% -> 0.06
L27: Profit | N27: =Model!C265 -> 11449567 | P27: 44804 | Q27: 0.0119824 | S27: =EOMONTH(S26,1) -> 44742 | T27: =T26+1 -> 18 | U27: =IF(T27<=$J$21,$X27,$T$6) -> 171873.33 | V27: =Y26 -> 40000000 | W27: =U27-X27 -> 0 | X27: =$J$19/$I$13*($S27-$S26)*V27 -> 171873.33 | Y27: =V27-W27 -> 40000000 | AA27: =AA26+0.25% -> 0.0625
B28: Unit Mix | L28: Multiple | N28: =Model!C266 -> 1.6785127 | P28: 44834 | Q28: 0.0119528 | S28: =EOMONTH(S27,1) -> 44773 | T28: =T27+1 -> 19 | U28: =IF(T28<=$J$21,$X28,$T$6) -> 177602.44 | V28: =Y27 -> 40000000 | W28: =U28-X28 -> 0 | X28: =$J$19/$I$13*($S28-$S27)*V28 -> 177602.44 | Y28: =V28-W28 -> 40000000 | AA28: =AA27+0.25% -> 0.065
B29: Type | C29: Count | D29: % of Total | F29: Unit Size | G29: Total SF | I29: Potential Rent | J29: Rent PSF | P29: 44865 | Q29: 0.0119603 | S29: =EOMONTH(S28,1) -> 44804 | T29: =T28+1 -> 20 | U29: =IF(T29<=$J$21,$X29,$T$6) -> 177602.44 | V29: =Y28 -> 40000000 | W29: =U29-X29 -> 0 | X29: =$J$19/$I$13*($S29-$S28)*V29 -> 177602.44 | Y29: =V29-W29 -> 40000000
B30: Studio | C30: 15 | D30: =C30/$C$34 -> 0.05 | F30: 600 | G30: =F30*C30 -> 9000 | I30: 1000 | J30: =IFERROR(I30/F30,"0") -> 1.6666667 | L30: GP Returns after Promote | P30: 44895 | Q30: 0.0119794 | S30: =EOMONTH(S29,1) -> 44834 | T30: =T29+1 -> 21 | U30: =IF(T30<=$J$21,$X30,$T$6) -> 171873.33 | V30: =Y29 -> 40000000 | W30: =U30-X30 -> 0 | X30: =$J$19/$I$13*($S30-$S29)*V30 -> 171873.33 | Y30: =V30-W30 -> 40000000 | AA30: Exit Cap | AB30: Renovation Premium
B31: 1 BR, 1 BA | C31: 155 | D31: =C31/$C$34 -> 0.51666667 | F31: 800 | G31: =F31*C31 -> 124000 | I31: 1300 | J31: =IFERROR(I31/F31,"0") -> 1.625 | L31: IRR | N31: =Model!C278 -> 0.60943713 | P31: 44926 | Q31: 0.0120267 | S31: =EOMONTH(S30,1) -> 44865 | T31: =T30+1 -> 22 | U31: =IF(T31<=$J$21,$X31,$T$6) -> 177602.44 | V31: =Y30 -> 40000000 | W31: =U31-X31 -> 0 | X31: =$J$19/$I$13*($S31-$S30)*V31 -> 177602.44 | Y31: =V31-W31 -> 40000000 | AA31: =IF(ISERROR(CONCATENATE(TEXT($N$21,"0.0%"),", ",TEXT($N$22/1000000,"$0.0"),"M, ",TEXT($N$23,"0.0x"))),0,CONCATENATE(TEXT($N$21,"0.0%"),", ",TEXT($N$22/1000000,"$0.0"),"M, ",TEXT($N$23,"0.0x"))) -> 27.5%, $15.9M, 1.8x | AB31: =AC31-25 -> 75 | AC31: =AD31-25 -> 100 | AD31: 125 | AE31: =AD31+25 -> 150 | AF31: =AE31+25 -> 175
B32: 2 BR, 2 BA | C32: 130 | D32: =C32/$C$34 -> 0.43333333 | F32: 1200 | G32: =F32*C32 -> 156000 | I32: 1750 | J32: =IFERROR(I32/F32,"0") -> 1.4583333 | L32: Profit | N32: =Model!C279 -> 4465703 | P32: 44957 | Q32: 0.012084 | S32: =EOMONTH(S31,1) -> 44895 | T32: =T31+1 -> 23 | U32: =IF(T32<=$J$21,$X32,$T$6) -> 171873.33 | V32: =Y31 -> 40000000 | W32: =U32-X32 -> 0 | X32: =$J$19/$I$13*($S32-$S31)*V32 -> 171873.33 | Y32: =V32-W32 -> 40000000 | AA32: =AA33-0.25% -> 0.045
B33: 3 BR, 2 BA | C33: 0 | D33: =C33/$C$34 -> 0 | F33: 0 | G33: =F33*C33 -> 0 | I33: 0 | J33: =IFERROR(I33/F33,0) -> 0 | L33: Multiple | N33: =Model!C280 -> 3.3817781 | P33: 44985 | Q33: 0.0121249 | S33: =EOMONTH(S32,1) -> 44926 | T33: =T32+1 -> 24 | U33: =IF(T33<=$J$21,$X33,$T$6) -> 177602.44 | V33: =Y32 -> 40000000 | W33: =U33-X33 -> 0 | X33: =$J$19/$I$13*($S33-$S32)*V33 -> 177602.44 | Y33: =V33-W33 -> 40000000 | AA33: =AA34-0.25% -> 0.0475
B34: Total | C34: =SUM(C30:C33) -> 300 | D34: =SUM(D30:D33) -> 1 | F34: =SUMPRODUCT(F30:F33,$C$30:$C$33)/$C$34 -> 963.33333 | G34: =SUM(G30:G33) -> 289000 | I34: =SUMPRODUCT(I30:I33,$C$30:$C$33)/$C$34 -> 1480 | J34: =SUMPRODUCT(J30:J33,$C$30:$C$33)/$C$34 -> 1.5548611 | P34: 45016 | Q34: 0.012174 | S34: =EOMONTH(S33,1) -> 44957 | T34: =T33+1 -> 25 | U34: =IF(T34<=$J$21,$X34,$T$6) -> 177602.44 | V34: =Y33 -> 40000000 | W34: =U34-X34 -> 0 | X34: =$J$19/$I$13*($S34-$S33)*V34 -> 177602.44 | Y34: =V34-W34 -> 40000000 | AA34: =AA35-0.25% -> 0.05
P35: 45046 | Q35: 0.0122224 | S35: =EOMONTH(S34,1) -> 44985 | T35: =T34+1 -> 26 | U35: =IF(T35<=$J$21,$X35,$T$6) -> 160415.11 | V35: =Y34 -> 40000000 | W35: =U35-X35 -> 0 | X35: =$J$19/$I$13*($S35-$S34)*V35 -> 160415.11 | Y35: =V35-W35 -> 40000000 | AA35: =AA36-0.25% -> 0.0525
B36: Lease-up Assumptions | E36: Timetable | P36: 45077 | Q36: 0.0122549 | S36: =EOMONTH(S35,1) -> 45016 | T36: =T35+1 -> 27 | U36: =IF(T36<=$J$21,$X36,$T$6) -> 177602.44 | V36: =Y35 -> 40000000 | W36: =U36-X36 -> 0 | X36: =$J$19/$I$13*($S36-$S35)*V36 -> 177602.44 | Y36: =V36-W36 -> 40000000 | AA36: 0.055
B37: Units Leased / Month | C37: 30 | F37: Month | G37: Start | H37: Duration | I37: End | J37: Month | P37: 45107 | Q37: 0.0122909 | S37: =EOMONTH(S36,1) -> 45046 | T37: =T36+1 -> 28 | U37: =IF(T37<=$J$21,$X37,$T$6) -> 171873.33 | V37: =Y36 -> 40000000 | W37: =U37-X37 -> 0 | X37: =$J$19/$I$13*($S37-$S36)*V37 -> 171873.33 | Y37: =V37-W37 -> 40000000 | AA37: =AA36+0.25% -> 0.0575
B38: Concessions | C38: 1 | E38: Acquisition | F38: 0 | G38: =E12 -> 44196 | H38: 1 | I38: =EOMONTH(G38,H38-1) -> 44196 | J38: =F38+H38-1 -> 0 | P38: 45138 | Q38: 0.0123245 | S38: =EOMONTH(S37,1) -> 45077 | T38: =T37+1 -> 29 | U38: =IF(T38<=$J$21,$X38,$T$6) -> 177602.44 | V38: =Y37 -> 40000000 | W38: =U38-X38 -> 0 | X38: =$J$19/$I$13*($S38-$S37)*V38 -> 177602.44 | Y38: =V38-W38 -> 40000000 | AA38: =AA37+0.25% -> 0.06
B39: Concession Burnoff | C39: 6 | E39: Soft Costs | F39: 3 | G39: =EOMONTH($G$38,F39) -> 44286 | H39: 20 | I39: =EOMONTH(G39,H39-1) -> 44865 | J39: =F39+H39-1 -> 22 | P39: 45169 | Q39: 0.0123451 | S39: =EOMONTH(S38,1) -> 45107 | T39: =T38+1 -> 30 | U39: =IF(T39<=$J$21,$X39,$T$6) -> 171873.33 | V39: =Y38 -> 40000000 | W39: =U39-X39 -> 0 | X39: =$J$19/$I$13*($S39-$S38)*V39 -> 171873.33 | Y39: =V39-W39 -> 40000000 | AA39: =AA38+0.25% -> 0.0625
B40: Pre-Construction Leasing | C40: 6 | E40: Hard Costs | F40: 7 | G40: =EOMONTH($G$38,F40) -> 44408 | H40: 16 | I40: =EOMONTH(G40,H40-1) -> 44865 | J40: =F40+H40-1 -> 22 | P40: 45199 | Q40: 0.0123718 | S40: =EOMONTH(S39,1) -> 45138 | T40: =T39+1 -> 31 | U40: =IF(T40<=$J$21,$X40,$T$6) -> 177602.44 | V40: =Y39 -> 40000000 | W40: =U40-X40 -> 0 | X40: =$J$19/$I$13*($S40-$S39)*V40 -> 177602.44 | Y40: =V40-W40 -> 40000000 | AA40: =AA39+0.25% -> 0.065
E41: Lease-up | F41: =J40-C40 -> 16 | G41: =EOMONTH($G$38,F41) -> 44681 | H41: =ROUNDUP(E8/C37,0) -> 10 | I41: =EOMONTH(G41,H41-1) -> 44957 | J41: =F41+H41-1 -> 25 | P41: 45230 | Q41: 0.0124011 | S41: =EOMONTH(S40,1) -> 45169 | T41: =T40+1 -> 32 | U41: =IF(T41<=$J$21,$X41,$T$6) -> 177602.44 | V41: =Y40 -> 40000000 | W41: =U41-X41 -> 0 | X41: =$J$19/$I$13*($S41-$S40)*V41 -> 177602.44 | Y41: =V41-W41 -> 40000000
E42: Stabilization | F42: =F41 -> 16 | G42: =G41 -> 44681 | H42: =J42-F42+1 -> 16 | I42: =EOMONTH(I41,C39) -> 45138 | J42: =J41+C39 -> 31 | P42: 45260 | Q42: 0.0124186 | S42: =EOMONTH(S41,1) -> 45199 | T42: =T41+1 -> 33 | U42: =IF(T42<=$J$21,$X42,$T$6) -> 171873.33 | V42: =Y41 -> 40000000 | W42: =U42-X42 -> 0 | X42: =$J$19/$I$13*($S42-$S41)*V42 -> 171873.33 | Y42: =V42-W42 -> 40000000
...

Sheet Model
B2: Model
B4: Acq Date | C4: ='Inputs & Drivers'!E12 -> 44196 | H4: 0 | I4: 1 | J4: 1 | K4: 1 | L4: 1 | M4: 1 | N4: 1 | O4: 1 | P4: 1 | Q4: 1 | R4: 1 | S4: 1 | T4: 1 | U4: =I4+1 -> 2 | V4: =J4+1 -> 2 | W4: =K4+1 -> 2 | X4: =L4+1 -> 2 | Y4: =M4+1 -> 2 | Z4: =N4+1 -> 2 | AA4: =O4+1 -> 2 | AB4: =P4+1 -> 2 | ... EJ4: =DX4+1 -> 11
B5: Exit Date | C5: ='Inputs & Drivers'!E14 -> 45291 | H5: 0 | I5: =++H5+1 -> 1 | J5: =++I5+1 -> 2 | K5: =++J5+1 -> 3 | L5: =++K5+1 -> 4 | M5: =++L5+1 -> 5 | N5: =++M5+1 -> 6 | O5: =++N5+1 -> 7 | P5: =++O5+1 -> 8 | ... EJ5: =++EI5+1 -> 132 | EL5: =H4 -> 0 | EM5: =EL5+1 -> 1 | EN5: =EM5+1 -> 2 | EO5: =EN5+1 -> 3 | EP5: =EO5+1 -> 4 | EQ5: =EP5+1 -> 5 | ER5: =EQ5+1 -> 6 | ES5: =ER5+1 -> 7 | ET5: =ES5+1 -> 8 | ... EW5: =EV5+1 -> 11
B6: Size | C6: ='Inputs & Drivers'!E8 -> 300 | F6: Total | H6: =C4 -> 44196 | I6: =EOMONTH(H6,1) -> 44227 | J6: =EOMONTH(I6,1) -> 44255 | K6: =EOMONTH(J6,1) -> 44286 | L6: =EOMONTH(K6,1) -> 44316 | M6: =EOMONTH(L6,1) -> 44347 | N6: =EOMONTH(M6,1) -> 44377 | O6: =EOMONTH(N6,1) -> 44408 | P6: =EOMONTH(O6,1) -> 44439 | ... EJ6: =EOMONTH(EI6,1) -> 48213 | EL6: =H6 -> 44196 | EM6: =EOMONTH(EL6,12) -> 44561 | EN6: =EOMONTH(EM6,12) -> 44926 | EO6: =EOMONTH(EN6,12) -> 45291 | EP6: =EOMONTH(EO6,12) -> 45657 | EQ6: =EOMONTH(EP6,12) -> 46022 | ER6: =EOMONTH(EQ6,12) -> 46387 | ES6: =EOMONTH(ER6,12) -> 46752 | ET6: =EOMONTH(ES6,12) -> 47118 | ... EW6: =EOMONTH(EV6,12) -> 48213
B8: Investment Month | H8: =H5 -> 0 | I8: =I5 -> 1 | J8: =J5 -> 2 | K8: =K5 -> 3 | L8: =L5 -> 4 | M8: =M5 -> 5 | N8: =N5 -> 6 | O8: =O5 -> 7 | ... EJ8: =EJ5 -> 132
B9: Construction Month | H9: =H5 -> 0 | I9: =IF(OR(Model!I$8<'Inputs & Drivers'!$F40,Model!I$8>'Inputs & Drivers'!$J40),0,IF(I$8='Inputs & Drivers'!$F40,1,Model!H9+1)) -> 0 | J9: =IF(OR(Model!J$8<'Inputs & Drivers'!$F40,Model!J$8>'Inputs & Drivers'!$J40),0,IF(J$8='Inputs & Drivers'!$F40,1,Model!I9+1)) -> 0 | K9: =IF(OR(Model!K$8<'Inputs & Drivers'!$F40,Model!K$8>'Inputs & Drivers'!$J40),0,IF(K$8='Inputs & Drivers'!$F40,1,Model!J9+1)) -> 0 | L9: =IF(OR(Model!L$8<'Inputs & Drivers'!$F40,Model!L$8>'Inputs & Drivers'!$J40),0,IF(L$8='Inputs & Drivers'!$F40,1,Model!K9+1)) -> 0 | M9: =IF(OR(Model!M$8<'Inputs & Drivers'!$F40,Model!M$8>'Inputs & Drivers'!$J40),0,IF(M$8='Inputs & Drivers'!$F40,1,Model!L9+1)) -> 0 | N9: =IF(OR(Model!N$8<'Inputs & Drivers'!$F40,Model!N$8>'Inputs & Drivers'!$J40),0,IF(N$8='Inputs & Drivers'!$F40,1,Model!M9+1)) -> 0 | O9: =IF(OR(Model!O$8<'Inputs & Drivers'!$F40,Model!O$8>'Inputs & Drivers'!$J40),0,IF(O$8='Inputs & Drivers'!$F40,1,Model!N9+1)) -> 1 | P9: =IF(OR(Model!P$8<'Inputs & Drivers'!$F40,Model!P$8>'Inputs & Drivers'!$J40),0,IF(P$8='Inputs & Drivers'!$F40,1,Model!O9+1)) -> 2 | ... DI9: =IF(OR(Model!DI$8<'Inputs & Drivers'!$F40,Model!DI$8>'Inputs & Drivers'!$J40),0,IF(DI$8='Inputs & Drivers'!$F40,1,Model!DH9+1)) -> 0
B10: Lease-up Month | I10: =IF(OR(Model!I$8<'Inputs & Drivers'!$F41,Model!I$8>'Inputs & Drivers'!$J41),0,IF(I$8='Inputs & Drivers'!$F41,1,Model!H10+1)) -> 0 | J10: =IF(OR(Model!J$8<'Inputs & Drivers'!$F41,Model!J$8>'Inputs & Drivers'!$J41),0,IF(J$8='Inputs & Drivers'!$F41,1,Model!I10+1)) -> 0 | K10: =IF(OR(Model!K$8<'Inputs & Drivers'!$F41,Model!K$8>'Inputs & Drivers'!$J41),0,IF(K$8='Inputs & Drivers'!$F41,1,Model!J10+1)) -> 0 | L10: =IF(OR(Model!L$8<'Inputs & Drivers'!$F41,Model!L$8>'Inputs & Drivers'!$J41),0,IF(L$8='Inputs & Drivers'!$F41,1,Model!K10+1)) -> 0 | M10: =IF(OR(Model!M$8<'Inputs & Drivers'!$F41,Model!M$8>'Inputs & Drivers'!$J41),0,IF(M$8='Inputs & Drivers'!$F41,1,Model!L10+1)) -> 0 | N10: =IF(OR(Model!N$8<'Inputs & Drivers'!$F41,Model!N$8>'Inputs & Drivers'!$J41),0,IF(N$8='Inputs & Drivers'!$F41,1,Model!M10+1)) -> 0 | O10: =IF(OR(Model!O$8<'Inputs & Drivers'!$F41,Model!O$8>'Inputs & Drivers'!$J41),0,IF(O$8='Inputs & Drivers'!$F41,1,Model!N10+1)) -> 0 | P10: =IF(OR(Model!P$8<'Inputs & Drivers'!$F41,Model!P$8>'Inputs & Drivers'!$J41),0,IF(P$8='Inputs & Drivers'!$F41,1,Model!O10+1)) -> 0 | ... DI10: =IF(OR(Model!DI$8<'Inputs & Drivers'!$F41,Model!DI$8>'Inputs & Drivers'!$J41),0,IF(DI$8='Inputs & Drivers'!$F41,1,Model!DH10+1)) -> 0
B11: Concession Month | I11: =IF(OR(Model!I$8<'Inputs & Drivers'!$F42,Model!I$8>'Inputs & Drivers'!$J42),0,IF(I$8='Inputs & Drivers'!$F42,1,Model!H11+1)) -> 0 | J11: =IF(OR(Model!J$8<'Inputs & Drivers'!$F42,Model!J$8>'Inputs & Drivers'!$J42),0,IF(J$8='Inputs & Drivers'!$F42,1,Model!I11+1)) -> 0 | K11: =IF(OR(Model!K$8<'Inputs & Drivers'!$F42,Model!K$8>'Inputs & Drivers'!$J42),0,IF(K$8='Inputs & Drivers'!$F42,1,Model!J11+1)) -> 0 | L11: =IF(OR(Model!L$8<'Inputs & Drivers'!$F42,Model!L$8>'Inputs & Drivers'!$J42),0,IF(L$8='Inputs & Drivers'!$F42,1,Model!K11+1)) -> 0 | M11: =IF(OR(Model!M$8<'Inputs & Drivers'!$F42,Model!M$8>'Inputs & Drivers'!$J42),0,IF(M$8='Inputs & Drivers'!$F42,1,Model!L11+1)) -> 0 | N11: =IF(OR(Model!N$8<'Inputs & Drivers'!$F42,Model!N$8>'Inputs & Drivers'!$J42),0,IF(N$8='Inputs & Drivers'!$F42,1,Model!M11+1)) -> 0 | O11: =IF(OR(Model!O$8<'Inputs & Drivers'!$F42,Model!O$8>'Inputs & Drivers'!$J42),0,IF(O$8='Inputs & Drivers'!$F42,1,Model!N11+1)) -> 0 | P11: =IF(OR(Model!P$8<'Inputs & Drivers'!$F42,Model!P$8>'Inputs & Drivers'!$J42),0,IF(P$8='Inputs & Drivers'!$F42,1,Model!O11+1)) -> 0 | ... DI11: =IF(OR(Model!DI$8<'Inputs & Drivers'!$F42,Model!DI$8>'Inputs & Drivers'!$J42),0,IF(DI$8='Inputs & Drivers'!$F42,1,Model!DH11+1)) -> 0
B13: Development Timeline
B14: Acquisition Costs | H14: =(1/'Inputs & Drivers'!$H38)*(Model!H$8>='Inputs & Drivers'!$F38)*(Model!H$8<='Inputs & Drivers'!$J38) -> 1 | I14: =(1/'Inputs & Drivers'!$H38)*(Model!I$8>='Inputs & Drivers'!$F38)*(Model!I$8<='Inputs & Drivers'!$J38) -> 0 | J14: =(1/'Inputs & Drivers'!$H38)*(Model!J$8>='Inputs & Drivers'!$F38)*(Model!J$8<='Inputs & Drivers'!$J38) -> 0 | K14: =(1/'Inputs & Drivers'!$H38)*(Model!K$8>='Inputs & Drivers'!$F38)*(Model!K$8<='Inputs & Drivers'!$J38) -> 0 | L14: =(1/'Inputs & Drivers'!$H38)*(Model!L$8>='Inputs & Drivers'!$F38)*(Model!L$8<='Inputs & Drivers'!$J38) -> 0 | M14: =(1/'Inputs & Drivers'!$H38)*(Model!M$8>='Inputs & Drivers'!$F38)*(Model!M$8<='Inputs & Drivers'!$J38) -> 0 | N14: =(1/'Inputs & Drivers'!$H38)*(Model!N$8>='Inputs & Drivers'!$F38)*(Model!N$8<='Inputs & Drivers'!$J38) -> 0 | O14: =(1/'Inputs & Drivers'!$H38)*(Model!O$8>='Inputs & Drivers'!$F38)*(Model!O$8<='Inputs & Drivers'!$J38) -> 0 | ... BJ14: =(1/'Inputs & Drivers'!$H38)*(Model!BJ$8>='Inputs & Drivers'!$F38)*(Model!BJ$8<='Inputs & Drivers'!$J38) -> 0 | EL14: =SUMIF($H$4:$EJ$4,EL$5,$H14:$EJ14) -> 1 | EM14: =SUMIF($H$4:$EJ$4,EM$5,$H14:$EJ14) -> 0 | EN14: =SUMIF($H$4:$EJ$4,EN$5,$H14:$EJ14) -> 0 | EO14: =SUMIF($H$4:$EJ$4,EO$5,$H14:$EJ14) -> 0 | EP14: =SUMIF($H$4:$EJ$4,EP$5,$H14:$EJ14) -> 0 | EQ14: =SUMIF($H$4:$EJ$4,EQ$5,$H14:$EJ14) -> 0 | ER14: =SUMIF($H$4:$EJ$4,ER$5,$H14:$EJ14) -> 0 | ES14: =SUMIF($H$4:$EJ$4,ES$5,$H14:$EJ14) -> 0 | ... EW14: =SUMIF($H$4:$EJ$4,EW$5,$H14:$EJ14) -> 0
B15: Soft Costs | H15: =(1/'Inputs & Drivers'!$H39)*(Model!H$8>='Inputs & Drivers'!$F39)*(Model!H$8<='Inputs & Drivers'!$J39) -> 0 | I15: =(1/'Inputs & Drivers'!$H39)*(Model!I$8>='Inputs & Drivers'!$F39)*(Model!I$8<='Inputs & Drivers'!$J39) -> 0 | J15: =(1/'Inputs & Drivers'!$H39)*(Model!J$8>='Inputs & Drivers'!$F39)*(Model!J$8<='Inputs & Drivers'!$J39) -> 0 | K15: =(1/'Inputs & Drivers'!$H39)*(Model!K$8>='Inputs & Drivers'!$F39)*(Model!K$8<='Inputs & Drivers'!$J39) -> 0.05 | L15: =(1/'Inputs & Drivers'!$H39)*(Model!L$8>='Inputs & Drivers'!$F39)*(Model!L$8<='Inputs & Drivers'!$J39) -> 0.05 | M15: =(1/'Inputs & Drivers'!$H39)*(Model!M$8>='Inputs & Drivers'!$F39)*(Model!M$8<='Inputs & Drivers'!$J39) -> 0.05 | N15: =(1/'Inputs & Drivers'!$H39)*(Model!N$8>='Inputs & Drivers'!$F39)*(Model!N$8<='Inputs & Drivers'!$J39) -> 0.05 | O15: =(1/'Inputs & Drivers'!$H39)*(Model!O$8>='Inputs & Drivers'!$F39)*(Model!O$8<='Inputs & Drivers'!$J39) -> 0.05 | ... AL15: =(1/'Inputs & Drivers'!$H39)*(Model!AL$8>='Inputs & Drivers'!$F39)*(Model!AL$8<='Inputs & Drivers'!$J39) -> 0 | EL15: =SUMIF($H$4:$EJ$4,EL$5,$H15:$EJ15) -> 0 | EM15: =SUMIF($H$4:$EJ$4,EM$5,$H15:$EJ15) -> 0.5 | EN15: =SUMIF($H$4:$EJ$4,EN$5,$H15:$EJ15) -> 0.5 | EO15: =SUMIF($H$4:$EJ$4,EO$5,$H15:$EJ15) -> 0 | EP15: =SUMIF($H$4:$EJ$4,EP$5,$H15:$EJ15) -> 0 | EQ15: =SUMIF($H$4:$EJ$4,EQ$5,$H15:$EJ15) -> 0 | ER15: =SUMIF($H$4:$EJ$4,ER$5,$H15:$EJ15) -> 0 | ES15: =SUMIF($H$4:$EJ$4,ES$5,$H15:$EJ15) -> 0 | ... EW15: =SUMIF($H$4:$EJ$4,EW$5,$H15:$EJ15) -> 0
B16: Hard Costs | H16: =(1/'Inputs & Drivers'!$H40)*(Model!H$8>='Inputs & Drivers'!$F40)*(Model!H$8<='Inputs & Drivers'!$J40) -> 0 | I16: =(1/'Inputs & Drivers'!$H40)*(Model!I$8>='Inputs & Drivers'!$F40)*(Model!I$8<='Inputs & Drivers'!$J40) -> 0 | J16: =(1/'Inputs & Drivers'!$H40)*(Model!J$8>='Inputs & Drivers'!$F40)*(Model!J$8<='Inputs & Drivers'!$J40) -> 0 | K16: =(1/'Inputs & Drivers'!$H40)*(Model!K$8>='Inputs & Drivers'!$F40)*(Model!K$8<='Inputs & Drivers'!$J40) -> 0 | L16: =(1/'Inputs & Drivers'!$H40)*(Model!L$8>='Inputs & Drivers'!$F40)*(Model!L$8<='Inputs & Drivers'!$J40) -> 0 | M16: =(1/'Inputs & Drivers'!$H40)*(Model!M$8>='Inputs & Drivers'!$F40)*(Model!M$8<='Inputs & Drivers'!$J40) -> 0 | N16: =(1/'Inputs & Drivers'!$H40)*(Model!N$8>='Inputs & Drivers'!$F40)*(Model!N$8<='Inputs & Drivers'!$J40) -> 0 | O16: =(1/'Inputs & Drivers'!$H40)*(Model!O$8>='Inputs & Drivers'!$F40)*(Model!O$8<='Inputs & Drivers'!$J40) -> 0.0625 | ... BQ16: =(1/'Inputs & Drivers'!$H40)*(Model!BQ$8>='Inputs & Drivers'!$F40)*(Model!BQ$8<='Inputs & Drivers'!$J40) -> 0 | EL16: =SUMIF($H$4:$EJ$4,EL$5,$H16:$EJ16) -> 0 | EM16: =SUMIF($H$4:$EJ$4,EM$5,$H16:$EJ16) -> 0.375 | EN16: =SUMIF($H$4:$EJ$4,EN$5,$H16:$EJ16) -> 0.625 | EO16: =SUMIF($H$4:$EJ$4,EO$5,$H16:$EJ16) -> 0 | EP16: =SUMIF($H$4:$EJ$4,EP$5,$H16:$EJ16) -> 0 | EQ16: =SUMIF($H$4:$EJ$4,EQ$5,$H16:$EJ16) -> 0 | ER16: =SUMIF($H$4:$EJ$4,ER$5,$H16:$EJ16) -> 0 | ES16: =SUMIF($H$4:$EJ$4,ES$5,$H16:$EJ16) -> 0 | ... EW16: =SUMIF($H$4:$EJ$4,EW$5,$H16:$EJ16) -> 0
B17: Other Development Costs | H17: =H15 -> 0 | I17: =I15 -> 0 | J17: =J15 -> 0 | K17: =K15 -> 0.05 | L17: =L15 -> 0.05 | M17: =M15 -> 0.05 | N17: =N15 -> 0.05 | O17: =O15 -> 0.05 | ... BF17: =BF15 -> 0 | EL17: =SUMIF($H$4:$EJ$4,EL$5,$H17:$EJ17) -> 0 | EM17: =SUMIF($H$4:$EJ$4,EM$5,$H17:$EJ17) -> 0.5 | EN17: =SUMIF($H$4:$EJ$4,EN$5,$H17:$EJ17) -> 0.5 | EO17: =SUMIF($H$4:$EJ$4,EO$5,$H17:$EJ17) -> 0 | EP17: =SUMIF($H$4:$EJ$4,EP$5,$H17:$EJ17) -> 0 | EQ17: =SUMIF($H$4:$EJ$4,EQ$5,$H17:$EJ17) -> 0 | ER17: =SUMIF($H$4:$EJ$4,ER$5,$H17:$EJ17) -> 0 | ES17: =SUMIF($H$4:$EJ$4,ES$5,$H17:$EJ17) -> 0 | ... EW17: =SUMIF($H$4:$EJ$4,EW$5,$H17:$EJ17) -> 0
B19: Lease-up Timeline
B20: Remaining Unleased Units | H20: =H22 -> 0 | I20: =$C$6-I22 -> 300 | J20: =$C$6-J22 -> 300 | K20: =$C$6-K22 -> 300 | L20: =$C$6-L22 -> 300 | M20: =$C$6-M22 -> 300 | N20: =$C$6-N22 -> 300 | O20: =$C$6-O22 -> 300 | P20: =$C$6-P22 -> 300 | ... EJ20: =$C$6-EJ22 -> 0
B22: BOP - Occupied Units | H22: 0 | I22: =H24 -> 0 | J22: =I24 -> 0 | K22: =J24 -> 0 | L22: =K24 -> 0 | M22: =L24 -> 0 | N22: =M24 -> 0 | O22: =N24 -> 0 | P22: =O24 -> 0 | ... EJ22: =EI24 -> 300 | EL22: 0 | EM22: =EL24 -> 0 | EN22: =EM24 -> 0 | EO22: =EN24 -> 270 | EP22: =EO24 -> 300 | EQ22: =EP24 -> 300 | ER22: =EQ24 -> 300 | ES22: =ER24 -> 300 | ET22: =ES24 -> 300 | ... EW22: =EV24 -> 300
B23: Units Leased | H23: =IF(H$8<'Inputs & Drivers'!$F$41,0,MIN('Inputs & Drivers'!$C$37,Model!H$20)) -> 0 | I23: =IF(I$8<'Inputs & Drivers'!$F$41,0,MIN('Inputs & Drivers'!$C$37,Model!I$20)) -> 0 | J23: =IF(J$8<'Inputs & Drivers'!$F$41,0,MIN('Inputs & Drivers'!$C$37,Model!J$20)) -> 0 | K23: =IF(K$8<'Inputs & Drivers'!$F$41,0,MIN('Inputs & Drivers'!$C$37,Model!K$20)) -> 0 | L23: =IF(L$8<'Inputs & Drivers'!$F$41,0,MIN('Inputs & Drivers'!$C$37,Model!L$20)) -> 0 | M23: =IF(M$8<'Inputs & Drivers'!$F$41,0,MIN('Inputs & Drivers'!$C$37,Model!M$20)) -> 0 | N23: =IF(N$8<'Inputs & Drivers'!$F$41,0,MIN('Inputs & Drivers'!$C$37,Model!N$20)) -> 0 | O23: =IF(O$8<'Inputs & Drivers'!$F$41,0,MIN('Inputs & Drivers'!$C$37,Model!O$20)) -> 0 | ... EJ23: =IF(EJ$8<'Inputs & Drivers'!$F$41,0,MIN('Inputs & Drivers'!$C$37,Model!EJ$20)) -> 0 | EL23: =SUMIF($H$4:$EJ$4,EL$5,$H23:$EJ23) -> 0 | EM23: =SUMIF($H$4:$EJ$4,EM$5,$H23:$EJ23) -> 0 | EN23: =SUMIF($H$4:$EJ$4,EN$5,$H23:$EJ23) -> 270 | EO23: =SUMIF($H$4:$EJ$4,EO$5,$H23:$EJ23) -> 30 | EP23: =SUMIF($H$4:$EJ$4,EP$5,$H23:$EJ23) -> 0 | EQ23: =SUMIF($H$4:$EJ$4,EQ$5,$H23:$EJ23) -> 0 | ER23: =SUMIF($H$4:$EJ$4,ER$5,$H23:$EJ23) -> 0 | ES23: =SUMIF($H$4:$EJ$4,ES$5,$H23:$EJ23) -> 0 | ... EW23: =SUMIF($H$4:$EJ$4,EW$5,$H23:$EJ23) -> 0
B24: EOP - Occupied Units | H24: =H23+H22 -> 0 | I24: =I23+I22 -> 0 | J24: =J23+J22 -> 0 | K24: =K23+K22 -> 0 | L24: =L23+L22 -> 0 | M24: =M23+M22 -> 0 | N24: =N23+N22 -> 0 | O24: =O23+O22 -> 0 | ... EJ24: =EJ23+EJ22 -> 300 | EL24: =SUM(EL22:EL23) -> 0 | EM24: =SUM(EM22:EM23) -> 0 | EN24: =SUM(EN22:EN23) -> 270 | EO24: =SUM(EO22:EO23) -> 300 | EP24: =SUM(EP22:EP23) -> 300 | EQ24: =SUM(EQ22:EQ23) -> 300 | ER24: =SUM(ER22:ER23) -> 300 | ES24: =SUM(ES22:ES23) -> 300 | ... EW24: =SUM(EW22:EW23) -> 300
B26: Other Revenue (per month)
B27: Utility Reimbursement | H27: 30 | I27: =H27*(1+(INDEX('Inputs & Drivers'!$G$68:$G$78,MATCH(Model!I$4,'Inputs & Drivers'!$B$68:$B$78))/12)) -> 30 | J27: =I27*(1+(INDEX('Inputs & Drivers'!$G$68:$G$78,MATCH(Model!J$4,'Inputs & Drivers'!$B$68:$B$78))/12)) -> 30 | K27: =J27*(1+(INDEX('Inputs & Drivers'!$G$68:$G$78,MATCH(Model!K$4,'Inputs & Drivers'!$B$68:$B$78))/12)) -> 30 | L27: =K27*(1+(INDEX('Inputs & Drivers'!$G$68:$G$78,MATCH(Model!L$4,'Inputs & Drivers'!$B$68:$B$78))/12)) -> 30 | M27: =L27*(1+(INDEX('Inputs & Drivers'!$G$68:$G$78,MATCH(Model!M$4,'Inputs & Drivers'!$B$68:$B$78))/12)) -> 30 | N27: =M27*(1+(INDEX('Inputs & Drivers'!$G$68:$G$78,MATCH(Model!N$4,'Inputs & Drivers'!$B$68:$B$78))/12)) -> 30 | O27: =N27*(1+(INDEX('Inputs & Drivers'!$G$68:$G$78,MATCH(Model!O$4,'Inputs & Drivers'!$B$68:$B$78))/12)) -> 30 | P27: =O27*(1+(INDEX('Inputs & Drivers'!$G$68:$G$78,MATCH(Model!P$4,'Inputs & Drivers'!$B$68:$B$78))/12)) -> 30 | ... EJ27: =EI27*(1+(INDEX('Inputs & Drivers'!$G$68:$G$78,MATCH(Model!EJ$4,'Inputs & Drivers'!$B$68:$B$78))/12)) -> 36.635983 | EL27: =SUMIF($H$6:$EJ$6,EL$6,$H27:$EJ27) -> 30 | EM27: =SUMIF($H$6:$EJ$6,EM$6,$H27:$EJ27) -> 30 | EN27: =SUMIF($H$6:$EJ$6,EN$6,$H27:$EJ27) -> 30.605531 | EO27: =SUMIF($H$6:$EJ$6,EO$6,$H27:$EJ27) -> 31.223284 | EP27: =SUMIF($H$6:$EJ$6,EP$6,$H27:$EJ27) -> 31.853505 | EQ27: =SUMIF($H$6:$EJ$6,EQ$6,$H27:$EJ27) -> 32.496448 | ER27: =SUMIF($H$6:$EJ$6,ER$6,$H27:$EJ27) -> 33.152368 | ES27: =SUMIF($H$6:$EJ$6,ES$6,$H27:$EJ27) -> 33.821527 | ... EW27: =SUMIF($H$6:$EJ$6,EW$6,$H27:$EJ27) -> 36.635983
B28: Parking Revenue | H28: 100 | I28: =H28*(1+(INDEX('Inputs & Drivers'!$G$68:$G$78,MATCH(Model!I$4,'Inputs & Drivers'!$B$68:$B$78))/12)) -> 100 | J28: =I28*(1+(INDEX('Inputs & Drivers'!$G$68:$G$78,MATCH(Model!J$4,'Inputs & Drivers'!$B$68:$B$78))/12)) -> 100 | K28: =J28*(1+(INDEX('Inputs & Drivers'!$G$68:$G$78,MATCH(Model!K$4,'Inputs & Drivers'!$B$68:$B$78))/12)) -> 100 | L28: =K28*(1+(INDEX('Inputs & Drivers'!$G$68:$G$78,MATCH(Model!L$4,'Inputs & Drivers'!$B$68:$B$78))/12)) -> 100 | M28: =L28*(1+(INDEX('Inputs & Drivers'!$G$68:$G$78,MATCH(Model!M$4,'Inputs & Drivers'!$B$68:$B$78))/12)) -> 100 | N28: =M28*(1+(INDEX('Inputs & Drivers'!$G$68:$G$78,MATCH(Model!N$4,'Inputs & Drivers'!$B$68:$B$78))/12)) -> 100 | O28: =N28*(1+(INDEX('Inputs & Drivers'!$G$68:$G$78,MATCH(Model!O$4,'Inputs & Drivers'!$B$68:$B$78))/12)) -> 100 | P28: =O28*(1+(INDEX('Inputs & Drivers'!$G$68:$G$78,MATCH(Model!P$4,'Inputs & Drivers'!$B$68:$B$78))/12)) -> 100 | ... EJ28: =EI28*(1+(INDEX('Inputs & Drivers'!$G$68:$G$78,MATCH(Model!EJ$4,'Inputs & Drivers'!$B$68:$B$78))/12)) -> 122.11994 | EL28: =SUMIF($H$6:$EJ$6,EL$6,$H28:$EJ28) -> 100 | EM28: =SUMIF($H$6:$EJ$6,EM$6,$H28:$EJ28) -> 100 | EN28: =SUMIF($H$6:$EJ$6,EN$6,$H28:$EJ28) -> 102.01844 | EO28: =SUMIF($H$6:$EJ$6,EO$6,$H28:$EJ28) -> 104.07761 | EP28: =SUMIF($H$6:$EJ$6,EP$6,$H28:$EJ28) -> 106.17835 | EQ28: =SUMIF($H$6:$EJ$6,EQ$6,$H28:$EJ28) -> 108.32149 | ER28: =SUMIF($H$6:$EJ$6,ER$6,$H28:$EJ28) -> 110.50789 | ES28: =SUMIF($H$6:$EJ$6,ES$6,$H28:$EJ28) -> 112.73842 | ... EW28: =SUMIF($H$6:$EJ$6,EW$6,$H28:$EJ28) -> 122.11994
B29: Other Revenue | H29: 25 | I29: =H29*(1+(INDEX('Inputs & Drivers'!$G$68:$G$78,MATCH(Model!I$4,'Inputs & Drivers'!$B$68:$B$78))/12)) -> 25 | J29: =I29*(1+(INDEX('Inputs & Drivers'!$G$68:$G$78,MATCH(Model!J$4,'Inputs & Drivers'!$B$68:$B$78))/12)) -> 25 | K29: =J29*(1+(INDEX('Inputs & Drivers'!$G$68:$G$78,MATCH(Model!K$4,'Inputs & Drivers'!$B$68:$B$78))/12)) -> 25 | L29: =K29*(1+(INDEX('Inputs & Drivers'!$G$68:$G$78,MATCH(Model!L$4,'Inputs & Drivers'!$B$68:$B$78))/12)) -> 25 | M29: =L29*(1+(INDEX('Inputs & Drivers'!$G$68:$G$78,MATCH(Model!M$4,'Inputs & Drivers'!$B$68:$B$78))/12)) -> 25 | N29: =M29*(1+(INDEX('Inputs & Drivers'!$G$68:$G$78,MATCH(Model!N$4,'Inputs & Drivers'!$B$68:$B$78))/12)) -> 25 | O29: =N29*(1+(INDEX('Inputs & Drivers'!$G$68:$G$78,MATCH(Model!O$4,'Inputs & Drivers'!$B$68:$B$78))/12)) -> 25 | P29: =O29*(1+(INDEX('Inputs & Drivers'!$G$68:$G$78,MATCH(Model!P$4,'Inputs & Drivers'!$B$68:$B$78))/12)) -> 25 | ... EJ29: =EI29*(1+(INDEX('Inputs & Drivers'!$G$68:$G$78,MATCH(Model!EJ$4,'Inputs & Drivers'!$B$68:$B$78))/12)) -> 30.529986 | EL29: =SUMIF($H$6:$EJ$6,EL$6,$H29:$EJ29) -> 25 | EM29: =SUMIF($H$6:$EJ$6,EM$6,$H29:$EJ29) -> 25 | EN29: =SUMIF($H$6:$EJ$6,EN$6,$H29:$EJ29) -> 25.504609 | EO29: =SUMIF($H$6:$EJ$6,EO$6,$H29:$EJ29) -> 26.019403 | EP29: =SUMIF($H$6:$EJ$6,EP$6,$H29:$EJ29) -> 26.544588 | EQ29: =SUMIF($H$6:$EJ$6,EQ$6,$H29:$EJ29) -> 27.080373 | ER29: =SUMIF($H$6:$EJ$6,ER$6,$H29:$EJ29) -> 27.626973 | ES29: =SUMIF($H$6:$EJ$6,ES$6,$H29:$EJ29) -> 28.184606 | ... EW29: =SUMIF($H$6:$EJ$6,EW$6,$H29:$EJ29) -> 30.529986
B31: Operating Expenses (per year)
B32: Repairs & Maintenance | H32: ='Inputs & Drivers'!I49 -> 600 | I32: =H32*(1+(INDEX('Inputs & Drivers'!$I$68:$I$78,MATCH(Model!I$4,'Inputs & Drivers'!$B$68:$B$78))/12)) -> 600 | J32: =I32*(1+(INDEX('Inputs & Drivers'!$I$68:$I$78,MATCH(Model!J$4,'Inputs & Drivers'!$B$68:$B$78))/12)) -> 600 | K32: =J32*(1+(INDEX('Inputs & Drivers'!$I$68:$I$78,MATCH(Model!K$4,'Inputs & Drivers'!$B$68:$B$78))/12)) -> 600 | L32: =K32*(1+(INDEX('Inputs & Drivers'!$I$68:$I$78,MATCH(Model!L$4,'Inputs & Drivers'!$B$68:$B$78))/12)) -> 600 | M32: =L32*(1+(INDEX('Inputs & Drivers'!$I$68:$I$78,MATCH(Model!M$4,'Inputs & Drivers'!$B$68:$B$78))/12)) -> 600 | N32: =M32*(1+(INDEX('Inputs & Drivers'!$I$68:$I$78,MATCH(Model!N$4,'Inputs & Drivers'!$B$68:$B$78))/12)) -> 600 | O32: =N32*(1+(INDEX('Inputs & Drivers'!$I$68:$I$78,MATCH(Model!O$4,'Inputs & Drivers'!$B$68:$B$78))/12)) -> 600 | P32: =O32*(1+(INDEX('Inputs & Drivers'!$I$68:$I$78,MATCH(Model!P$4,'Inputs & Drivers'!$B$68:$B$78))/12)) -> 600 | ... EJ32: =EI32*(1+(INDEX('Inputs & Drivers'!$I$68:$I$78,MATCH(Model!EJ$4,'Inputs & Drivers'!$B$68:$B$78))/12)) -> 801.57302 | EL32: =SUMIF($H$6:$EJ$6,EL$6,$H32:$EJ32) -> 600 | EM32: =SUMIF($H$6:$EJ$6,EM$6,$H32:$EJ32) -> 600 | EN32: =SUMIF($H$6:$EJ$6,EN$6,$H32:$EJ32) -> 612.11061 | EO32: =SUMIF($H$6:$EJ$6,EO$6,$H32:$EJ32) -> 630.72854 | EP32: =SUMIF($H$6:$EJ$6,EP$6,$H32:$EJ32) -> 649.91276 | EQ32: =SUMIF($H$6:$EJ$6,EQ$6,$H32:$EJ32) -> 669.68047 | ER32: =SUMIF($H$6:$EJ$6,ER$6,$H32:$EJ32) -> 690.04945 | ES32: =SUMIF($H$6:$EJ$6,ES$6,$H32:$EJ32) -> 711.03796 | ... EW32: =SUMIF($H$6:$EJ$6,EW$6,$H32:$EJ32) -> 801.57302
B33: Turnover | H33: ='Inputs & Drivers'!I50 -> 250 | I33: =H33*(1+(INDEX('Inputs & Drivers'!$I$68:$I$78,MATCH(Model!I$4,'Inputs & Drivers'!$B$68:$B$78))/12)) -> 250 | J33: =I33*(1+(INDEX('Inputs & Drivers'!$I$68:$I$78,MATCH(Model!J$4,'Inputs & Drivers'!$B$68:$B$78))/12)) -> 250 | K33: =J33*(1+(INDEX('Inputs & Drivers'!$I$68:$I$78,MATCH(Model!K$4,'Inputs & Drivers'!$B$68:$B$78))/12)) -> 250 | L33: =K33*(1+(INDEX('Inputs & Drivers'!$I$68:$I$78,MATCH(Model!L$4,'Inputs & Drivers'!$B$68:$B$78))/12)) -> 250 | M33: =L33*(1+(INDEX('Inputs & Drivers'!$I$68:$I$78,MATCH(Model!M$4,'Inputs & Drivers'!$B$68:$B$78))/12)) -> 250 | N33: =M33*(1+(INDEX('Inputs & Drivers'!$I$68:$I$78,MATCH(Model!N$4,'Inputs & Drivers'!$B$68:$B$78))/12)) -> 250 | O33: =N33*(1+(INDEX('Inputs & Drivers'!$I$68:$I$78,MATCH(Model!O$4,'Inputs & Drivers'!$B$68:$B$78))/12)) -> 250 | P33: =O33*(1+(INDEX('Inputs & Drivers'!$I$68:$I$78,MATCH(Model!P$4,'Inputs & Drivers'!$B$68:$B$78))/12)) -> 250 | ... EJ33: =EI33*(1+(INDEX('Inputs & Drivers'!$I$68:$I$78,MATCH(Model!EJ$4,'Inputs & Drivers'!$B$68:$B$78))/12)) -> 333.98876 | EL33: =SUMIF($H$6:$EJ$6,EL$6,$H33:$EJ33) -> 250 | EM33: =SUMIF($H$6:$EJ$6,EM$6,$H33:$EJ33) -> 250 | EN33: =SUMIF($H$6:$EJ$6,EN$6,$H33:$EJ33) -> 255.04609 | EO33: =SUMIF($H$6:$EJ$6,EO$6,$H33:$EJ33) -> 262.80356 | EP33: =SUMIF($H$6:$EJ$6,EP$6,$H33:$EJ33) -> 270.79698 | EQ33: =SUMIF($H$6:$EJ$6,EQ$6,$H33:$EJ33) -> 279.03353 | ER33: =SUMIF($H$6:$EJ$6,ER$6,$H33:$EJ33) -> 287.5206 | ES33: =SUMIF($H$6:$EJ$6,ES$6,$H33:$EJ33) -> 296.26582 | ... EW33: =SUMIF($H$6:$EJ$6,EW$6,$H33:$EJ33) -> 333.98876
B34: Marketing | H34: ='Inputs & Drivers'!I51 -> 150 | I34: =H34*(1+(INDEX('Inputs & Drivers'!$I$68:$I$78,MATCH(Model!I$4,'Inputs & Drivers'!$B$68:$B$78))/12)) -> 150 | J34: =I34*(1+(INDEX('Inputs & Drivers'!$I$68:$I$78,MATCH(Model!J$4,'Inputs & Drivers'!$B$68:$B$78))/12)) -> 150 | K34: =J34*(1+(INDEX('Inputs & Drivers'!$I$68:$I$78,MATCH(Model!K$4,'Inputs & Drivers'!$B$68:$B$78))/12)) -> 150 | L34: =K34*(1+(INDEX('Inputs & Drivers'!$I$68:$I$78,MATCH(Model!L$4,'Inputs & Drivers'!$B$68:$B$78))/12)) -> 150 | M34: =L34*(1+(INDEX('Inputs & Drivers'!$I$68:$I$78,MATCH(Model!M$4,'Inputs & Drivers'!$B$68:$B$78))/12)) -> 150 | N34: =M34*(1+(INDEX('Inputs & Drivers'!$I$68:$I$78,MATCH(Model!N$4,'Inputs & Drivers'!$B$68:$B$78))/12)) -> 150 | O34: =N34*(1+(INDEX('Inputs & Drivers'!$I$68:$I$78,MATCH(Model!O$4,'Inputs & Drivers'!$B$68:$B$78))/12)) -> 150 | P34: =O34*(1+(INDEX('Inputs & Drivers'!$I$68:$I$78,MATCH(Model!P$4,'Inputs & Drivers'!$B$68:$B$78))/12)) -> 150 | ... EJ34: =EI34*(1+(INDEX('Inputs & Drivers'!$I$68:$I$78,MATCH(Model!EJ$4,'Inputs & Drivers'!$B$68:$B$78))/12)) -> 200.39325 | EL34: =SUMIF($H$6:$EJ$6,EL$6,$H34:$EJ34) -> 150 | EM34: =SUMIF($H$6:$EJ$6,EM$6,$H34:$EJ34) -> 150 | EN34: =SUMIF($H$6:$EJ$6,EN$6,$H34:$EJ34) -> 153.02765 | EO34: =SUMIF($H$6:$EJ$6,EO$6,$H34:$EJ34) -> 157.68214 | EP34: =SUMIF($H$6:$EJ$6,EP$6,$H34:$EJ34) -> 162.47819 | EQ34: =SUMIF($H$6:$EJ$6,EQ$6,$H34:$EJ34) -> 167.42012 | ER34: =SUMIF($H$6:$EJ$6,ER$6,$H34:$EJ34) -> 172.51236 | ES34: =SUMIF($H$6:$EJ$6,ES$6,$H34:$EJ34) -> 177.75949 | ... EW34: =SUMIF($H$6:$EJ$6,EW$6,$H34:$EJ34) -> 200.39325
B35: General & Administrative | H35: ='Inputs & Drivers'!I52 -> 375 | I35: =H35*(1+(INDEX('Inputs & Drivers'!$I$68:$I$78,MATCH(Model!I$4,'Inputs & Drivers'!$B$68:$B$78))/12)) -> 375 | J35: =I35*(1+(INDEX('Inputs & Drivers'!$I$68:$I$78,MATCH(Model!J$4,'Inputs & Drivers'!$B$68:$B$78))/12)) -> 375 | K35: =J35*(1+(INDEX('Inputs & Drivers'!$I$68:$I$78,MATCH(Model!K$4,'Inputs & Drivers'!$B$68:$B$78))/12)) -> 375 | L35: =K35*(1+(INDEX('Inputs & Drivers'!$I$68:$I$78,MATCH(Model!L$4,'Inputs & Drivers'!$B$68:$B$78))/12)) -> 375 | M35: =L35*(1+(INDEX('Inputs & Drivers'!$I$68:$I$78,MATCH(Model!M$4,'Inputs & Drivers'!$B$68:$B$78))/12)) -> 375 | N35: =M35*(1+(INDEX('Inputs & Drivers'!$I$68:$I$78,MATCH(Model!N$4,'Inputs & Drivers'!$B$68:$B$78))/12)) -> 375 | O35: =N35*(1+(INDEX('Inputs & Drivers'!$I$68:$I$78,MATCH(Model!O$4,'Inputs & Drivers'!$B$68:$B$78))/12)) -> 375 | P35: =O35*(1+(INDEX('Inputs & Drivers'!$I$68:$I$78,MATCH(Model!P$4,'Inputs & Drivers'!$B$68:$B$78))/12)) -> 375 | ... EJ35: =EI35*(1+(INDEX('Inputs & Drivers'!$I$68:$I$78,MATCH(Model!EJ$4,'Inputs & Drivers'!$B$68:$B$78))/12)) -> 500.98314 | EL35: =SUMIF($H$6:$EJ$6,EL$6,$H35:$EJ35) -> 375 | EM35: =SUMIF($H$6:$EJ$6,EM$6,$H35:$EJ35) -> 375 | EN35: =SUMIF($H$6:$EJ$6,EN$6,$H35:$EJ35) -> 382.56913 | EO35: =SUMIF($H$6:$EJ$6,EO$6,$H35:$EJ35) -> 394.20534 | EP35: =SUMIF($H$6:$EJ$6,EP$6,$H35:$EJ35) -> 406.19547 | EQ35: =SUMIF($H$6:$EJ$6,EQ$6,$H35:$EJ35) -> 418.5503 | ER35: =SUMIF($H$6:$EJ$6,ER$6,$H35:$EJ35) -> 431.2809 | ES35: =SUMIF($H$6:$EJ$6,ES$6,$H35:$EJ35) -> 444.39873 | ... EW35: =SUMIF($H$6:$EJ$6,EW$6,$H35:$EJ35) -> 500.98314
B36: Payroll | H36: ='Inputs & Drivers'!I53 -> 1100 | I36: =H36*(1+(INDEX('Inputs & Drivers'!$I$68:$I$78,MATCH(Model!I$4,'Inputs & Drivers'!$B$68:$B$78))/12)) -> 1100 | J36: =I36*(1+(INDEX('Inputs & Drivers'!$I$68:$I$78,MATCH(Model!J$4,'Inputs & Drivers'!$B$68:$B$78))/12)) -> 1100 | K36: =J36*(1+(INDEX('Inputs & Drivers'!$I$68:$I$78,MATCH(Model!K$4,'Inputs & Drivers'!$B$68:$B$78))/12)) -> 1100 | L36: =K36*(1+(INDEX('Inputs & Drivers'!$I$68:$I$78,MATCH(Model!L$4,'Inputs & Drivers'!$B$68:$B$78))/12)) -> 1100 | M36: =L36*(1+(INDEX('Inputs & Drivers'!$I$68:$I$78,MATCH(Model!M$4,'Inputs & Drivers'!$B$68:$B$78))/12)) -> 1100 | N36: =M36*(1+(INDEX('Inputs & Drivers'!$I$68:$I$78,MATCH(Model!N$4,'Inputs & Drivers'!$B$68:$B$78))/12)) -> 1100 | O36: =N36*(1+(INDEX('Inputs & Drivers'!$I$68:$I$78,MATCH(Model!O$4,'Inputs & Drivers'!$B$68:$B$78))/12)) -> 1100 | P36: =O36*(1+(INDEX('Inputs & Drivers'!$I$68:$I$78,MATCH(Model!P$4,'Inputs & Drivers'!$B$68:$B$78))/12)) -> 1100 | ... EJ36: =EI36*(1+(INDEX('Inputs & Drivers'!$I$68:$I$78,MATCH(Model!EJ$4,'Inputs & Drivers'!$B$68:$B$78))/12)) -> 1469.5505 | EL36: =SUMIF($H$6:$EJ$6,EL$6,$H36:$EJ36) -> 1100 | EM36: =SUMIF($H$6:$EJ$6,EM$6,$H36:$EJ36) -> 1100 | EN36: =SUMIF($H$6:$EJ$6,EN$6,$H36:$EJ36) -> 1122.2028 | EO36: =SUMIF($H$6:$EJ$6,EO$6,$H36:$EJ36) -> 1156.3357 | EP36: =SUMIF($H$6:$EJ$6,EP$6,$H36:$EJ36) -> 1191.5067 | EQ36: =SUMIF($H$6:$EJ$6,EQ$6,$H36:$EJ36) -> 1227.7475 | ER36: =SUMIF($H$6:$EJ$6,ER$6,$H36:$EJ36) -> 1265.0907 | ES36: =SUMIF($H$6:$EJ$6,ES$6,$H36:$EJ36) -> 1303.5696 | ... EW36: =SUMIF($H$6:$EJ$6,EW$6,$H36:$EJ36) -> 1469.5505
B37: Management Fees | H37: ='Inputs & Drivers'!I54 -> 448.107 | I37: =H37*(1+(INDEX('Inputs & Drivers'!$I$68:$I$78,MATCH(Model!I$4,'Inputs & Drivers'!$B$68:$B$78))/12)) -> 448.107 | J37: =I37*(1+(INDEX('Inputs & Drivers'!$I$68:$I$78,MATCH(Model!J$4,'Inputs & Drivers'!$B$68:$B$78))/12)) -> 448.107 | K37: =J37*(1+(INDEX('Inputs & Drivers'!$I$68:$I$78,MATCH(Model!K$4,'Inputs & Drivers'!$B$68:$B$78))/12)) -> 448.107 | L37: =K37*(1+(INDEX('Inputs & Drivers'!$I$68:$I$78,MATCH(Model!L$4,'Inputs & Drivers'!$B$68:$B$78))/12)) -> 448.107 | M37: =L37*(1+(INDEX('Inputs & Drivers'!$I$68:$I$78,MATCH(Model!M$4,'Inputs & Drivers'!$B$68:$B$78))/12)) -> 448.107 | N37: =M37*(1+(INDEX('Inputs & Drivers'!$I$68:$I$78,MATCH(Model!N$4,'Inputs & Drivers'!$B$68:$B$78))/12)) -> 448.107 | O37: =N37*(1+(INDEX('Inputs & Drivers'!$I$68:$I$78,MATCH(Model!O$4,'Inputs & Drivers'!$B$68:$B$78))/12)) -> 448.107 | P37: =O37*(1+(INDEX('Inputs & Drivers'!$I$68:$I$78,MATCH(Model!P$4,'Inputs & Drivers'!$B$68:$B$78))/12)) -> 448.107 | ... EJ37: =EI37*(1+(INDEX('Inputs & Drivers'!$I$68:$I$78,MATCH(Model!EJ$4,'Inputs & Drivers'!$B$68:$B$78))/12)) -> 598.6508 | EL37: =SUMIF($H$6:$EJ$6,EL$6,$H37:$EJ37) -> 448.107 | EM37: =SUMIF($H$6:$EJ$6,EM$6,$H37:$EJ37) -> 448.107 | EN37: =SUMIF($H$6:$EJ$6,EN$6,$H37:$EJ37) -> 457.15175 | EO37: =SUMIF($H$6:$EJ$6,EO$6,$H37:$EJ37) -> 471.05646 | EP37: =SUMIF($H$6:$EJ$6,EP$6,$H37:$EJ37) -> 485.38409 | EQ37: =SUMIF($H$6:$EJ$6,EQ$6,$H37:$EJ37) -> 500.14751 | ER37: =SUMIF($H$6:$EJ$6,ER$6,$H37:$EJ37) -> 515.35998 | ES37: =SUMIF($H$6:$EJ$6,ES$6,$H37:$EJ37) -> 531.03515 | ... EW37: =SUMIF($H$6:$EJ$6,EW$6,$H37:$EJ37) -> 598.6508
B38: Utilities | H38: ='Inputs & Drivers'!I55 -> 175 | I38: =H38*(1+(INDEX('Inputs & Drivers'!$I$68:$I$78,MATCH(Model!I$4,'Inputs & Drivers'!$B$68:$B$78))/12)) -> 175 | J38: =I38*(1+(INDEX('Inputs & Drivers'!$I$68:$I$78,MATCH(Model!J$4,'Inputs & Drivers'!$B$68:$B$78))/12)) -> 175 | K38: =J38*(1+(INDEX('Inputs & Drivers'!$I$68:$I$78,MATCH(Model!K$4,'Inputs & Drivers'!$B$68:$B$78))/12)) -> 175 | L38: =K38*(1+(INDEX('Inputs & Drivers'!$I$68:$I$78,MATCH(Model!L$4,'Inputs & Drivers'!$B$68:$B$78))/12)) -> 175 | M38: =L38*(1+(INDEX('Inputs & Drivers'!$I$68:$I$78,MATCH(Model!M$4,'Inputs & Drivers'!$B$68:$B$78))/12)) -> 175 | N38: =M38*(1+(INDEX('Inputs & Drivers'!$I$68:$I$78,MATCH(Model!N$4,'Inputs & Drivers'!$B$68:$B$78))/12)) -> 175 | O38: =N38*(1+(INDEX('Inputs & Drivers'!$I$68:$I$78,MATCH(Model!O$4,'Inputs & Drivers'!$B$68:$B$78))/12)) -> 175 | P38: =O38*(1+(INDEX('Inputs & Drivers'!$I$68:$I$78,MATCH(Model!P$4,'Inputs & Drivers'!$B$68:$B$78))/12)) -> 175 | ... EJ38: =EI38*(1+(INDEX('Inputs & Drivers'!$I$68:$I$78,MATCH(Model!EJ$4,'Inputs & Drivers'!$B$68:$B$78))/12)) -> 233.79213 | EL38: =SUMIF($H$6:$EJ$6,EL$6,$H38:$EJ38) -> 175 | EM38: =SUMIF($H$6:$EJ$6,EM$6,$H38:$EJ38) -> 175 | EN38: =SUMIF($H$6:$EJ$6,EN$6,$H38:$EJ38) -> 178.53226 | EO38: =SUMIF($H$6:$EJ$6,EO$6,$H38:$EJ38) -> 183.96249 | EP38: =SUMIF($H$6:$EJ$6,EP$6,$H38:$EJ38) -> 189.55789 | EQ38: =SUMIF($H$6:$EJ$6,EQ$6,$H38:$EJ38) -> 195.32347 | ER38: =SUMIF($H$6:$EJ$6,ER$6,$H38:$EJ38) -> 201.26442 | ES38: =SUMIF($H$6:$EJ$6,ES$6,$H38:$EJ38) -> 207.38607 | ... EW38: =SUMIF($H$6:$EJ$6,EW$6,$H38:$EJ38) -> 233.79213
B39: Real Estate Taxes | H39: ='Inputs & Drivers'!I56 -> 2166.6667 | I39: =H39*(1+(INDEX('Inputs & Drivers'!$J$68:$J$78,MATCH(Model!I$4,'Inputs & Drivers'!$B$68:$B$78))/12)) -> 2166.6667 | J39: =I39*(1+(INDEX('Inputs & Drivers'!$J$68:$J$78,MATCH(Model!J$4,'Inputs & Drivers'!$B$68:$B$78))/12)) -> 2166.6667 | K39: =J39*(1+(INDEX('Inputs & Drivers'!$J$68:$J$78,MATCH(Model!K$4,'Inputs & Drivers'!$B$68:$B$78))/12)) -> 2166.6667 | L39: =K39*(1+(INDEX('Inputs & Drivers'!$J$68:$J$78,MATCH(Model!L$4,'Inputs & Drivers'!$B$68:$B$78))/12)) -> 2166.6667 | M39: =L39*(1+(INDEX('Inputs & Drivers'!$J$68:$J$78,MATCH(Model!M$4,'Inputs & Drivers'!$B$68:$B$78))/12)) -> 2166.6667 | N39: =M39*(1+(INDEX('Inputs & Drivers'!$J$68:$J$78,MATCH(Model!N$4,'Inputs & Drivers'!$B$68:$B$78))/12)) -> 2166.6667 | O39: =N39*(1+(INDEX('Inputs & Drivers'!$J$68:$J$78,MATCH(Model!O$4,'Inputs & Drivers'!$B$68:$B$78))/12)) -> 2166.6667 | P39: =O39*(1+(INDEX('Inputs & Drivers'!$J$68:$J$78,MATCH(Model!P$4,'Inputs & Drivers'!$B$68:$B$78))/12)) -> 2166.6667 | ... EJ39: =EI39*(1+(INDEX('Inputs & Drivers'!$J$68:$J$78,MATCH(Model!EJ$4,'Inputs & Drivers'!$B$68:$B$78))/12)) -> 2645.9321 | EL39: =SUMIF($H$6:$EJ$6,EL$6,$H39:$EJ39) -> 2166.6667 | EM39: =SUMIF($H$6:$EJ$6,EM$6,$H39:$EJ39) -> 2166.6667 | EN39: =SUMIF($H$6:$EJ$6,EN$6,$H39:$EJ39) -> 2210.3994 | EO39: =SUMIF($H$6:$EJ$6,EO$6,$H39:$EJ39) -> 2255.0149 | EP39: =SUMIF($H$6:$EJ$6,EP$6,$H39:$EJ39) -> 2300.5309 | EQ39: =SUMIF($H$6:$EJ$6,EQ$6,$H39:$EJ39) -> 2346.9657 | ER39: =SUMIF($H$6:$EJ$6,ER$6,$H39:$EJ39) -> 2394.3377 | ES39: =SUMIF($H$6:$EJ$6,ES$6,$H39:$EJ39) -> 2442.6658 | ... EW39: =SUMIF($H$6:$EJ$6,EW$6,$H39:$EJ39) -> 2645.9321
B40: Property Insurance | H40: ='Inputs & Drivers'!I57 -> 275 | I40: =H40*(1+(INDEX('Inputs & Drivers'!$I$68:$I$78,MATCH(Model!I$4,'Inputs & Drivers'!$B$68:$B$78))/12)) -> 275 | J40: =I40*(1+(INDEX('Inputs & Drivers'!$I$68:$I$78,MATCH(Model!J$4,'Inputs & Drivers'!$B$68:$B$78))/12)) -> 275 | K40: =J40*(1+(INDEX('Inputs & Drivers'!$I$68:$I$78,MATCH(Model!K$4,'Inputs & Drivers'!$B$68:$B$78))/12)) -> 275 | L40: =K40*(1+(INDEX('Inputs & Drivers'!$I$68:$I$78,MATCH(Model!L$4,'Inputs & Drivers'!$B$68:$B$78))/12)) -> 275 | M40: =L40*(1+(INDEX('Inputs & Drivers'!$I$68:$I$78,MATCH(Model!M$4,'Inputs & Drivers'!$B$68:$B$78))/12)) -> 275 | N40: =M40*(1+(INDEX('Inputs & Drivers'!$I$68:$I$78,MATCH(Model!N$4,'Inputs & Drivers'!$B$68:$B$78))/12)) -> 275 | O40: =N40*(1+(INDEX('Inputs & Drivers'!$I$68:$I$78,MATCH(Model!O$4,'Inputs & Drivers'!$B$68:$B$78))/12)) -> 275 | P40: =O40*(1+(INDEX('Inputs & Drivers'!$I$68:$I$78,MATCH(Model!P$4,'Inputs & Drivers'!$B$68:$B$78))/12)) -> 275 | ... EJ40: =EI40*(1+(INDEX('Inputs & Drivers'!$I$68:$I$78,MATCH(Model!EJ$4,'Inputs & Drivers'!$B$68:$B$78))/12)) -> 367.38763 | EL40: =SUMIF($H$6:$EJ$6,EL$6,$H40:$EJ40) -> 275 | EM40: =SUMIF($H$6:$EJ$6,EM$6,$H40:$EJ40) -> 275 | EN40: =SUMIF($H$6:$EJ$6,EN$6,$H40:$EJ40) -> 280.5507 | EO40: =SUMIF($H$6:$EJ$6,EO$6,$H40:$EJ40) -> 289.08392 | EP40: =SUMIF($H$6:$EJ$6,EP$6,$H40:$EJ40) -> 297.87668 | EQ40: =SUMIF($H$6:$EJ$6,EQ$6,$H40:$EJ40) -> 306.93688 | ER40: =SUMIF($H$6:$EJ$6,ER$6,$H40:$EJ40) -> 316.27266 | ES40: =SUMIF($H$6:$EJ$6,ES$6,$H40:$EJ40) -> 325.8924 | ... EW40: =SUMIF($H$6:$EJ$6,EW$6,$H40:$EJ40) -> 367.38763
B41: Capital Reserves | H41: ='Inputs & Drivers'!I59 -> 150 | I41: =H41 -> 150 | J41: =I41 -> 150 | K41: =J41 -> 150 | L41: =K41 -> 150 | M41: =L41 -> 150 | N41: =M41 -> 150 | O41: =N41 -> 150 | P41: =O41 -> 150 | ... EJ41: =EI41 -> 150 | EL41: =SUMIF($H$6:$EJ$6,EL$6,$H41:$EJ41) -> 150 | EM41: =SUMIF($H$6:$EJ$6,EM$6,$H41:$EJ41) -> 150 | EN41: =SUMIF($H$6:$EJ$6,EN$6,$H41:$EJ41) -> 150 | EO41: =SUMIF($H$6:$EJ$6,EO$6,$H41:$EJ41) -> 150 | EP41: =SUMIF($H$6:$EJ$6,EP$6,$H41:$EJ41) -> 150 | EQ41: =SUMIF($H$6:$EJ$6,EQ$6,$H41:$EJ41) -> 150 | ER41: =SUMIF($H$6:$EJ$6,ER$6,$H41:$EJ41) -> 150 | ES41: =SUMIF($H$6:$EJ$6,ES$6,$H41:$EJ41) -> 150 | ... EW41: =SUMIF($H$6:$EJ$6,EW$6,$H41:$EJ41) -> 150
B43: Rent Growth | I43: =INDEX('Inputs & Drivers'!$E$68:$E$78,MATCH(Model!I$4,'Inputs & Drivers'!$B$68:$B$78))/12 -> 0 | J43: =INDEX('Inputs & Drivers'!$E$68:$E$78,MATCH(Model!J$4,'Inputs & Drivers'!$B$68:$B$78))/12 -> 0 | K43: =INDEX('Inputs & Drivers'!$E$68:$E$78,MATCH(Model!K$4,'Inputs & Drivers'!$B$68:$B$78))/12 -> 0 | L43: =INDEX('Inputs & Drivers'!$E$68:$E$78,MATCH(Model!L$4,'Inputs & Drivers'!$B$68:$B$78))/12 -> 0 | M43: =INDEX('Inputs & Drivers'!$E$68:$E$78,MATCH(Model!M$4,'Inputs & Drivers'!$B$68:$B$78))/12 -> 0 | N43: =INDEX('Inputs & Drivers'!$E$68:$E$78,MATCH(Model!N$4,'Inputs & Drivers'!$B$68:$B$78))/12 -> 0 | O43: =INDEX('Inputs & Drivers'!$E$68:$E$78,MATCH(Model!O$4,'Inputs & Drivers'!$B$68:$B$78))/12 -> 0 | P43: =INDEX('Inputs & Drivers'!$E$68:$E$78,MATCH(Model!P$4,'Inputs & Drivers'!$B$68:$B$78))/12 -> 0 | ... EJ43: =INDEX('Inputs & Drivers'!$E$68:$E$78,MATCH(Model!EJ$4,'Inputs & Drivers'!$B$68:$B$78))/12 -> 0.0025 | EL43: =SUMIF($H$4:$EJ$4,EL$5,$H43:$EJ43) -> 0 | EM43: =SUMIF($H$4:$EJ$4,EM$5,$H43:$EJ43) -> 0 | EN43: =SUMIF($H$4:$EJ$4,EN$5,$H43:$EJ43) -> 0.02 | EO43: =SUMIF($H$4:$EJ$4,EO$5,$H43:$EJ43) -> 0.03 | EP43: =SUMIF($H$4:$EJ$4,EP$5,$H43:$EJ43) -> 0.03 | EQ43: =SUMIF($H$4:$EJ$4,EQ$5,$H43:$EJ43) -> 0.03 | ER43: =SUMIF($H$4:$EJ$4,ER$5,$H43:$EJ43) -> 0.03 | ES43: =SUMIF($H$4:$EJ$4,ES$5,$H43:$EJ43) -> 0.03 | ... EW43: =SUMIF($H$4:$EJ$4,EW$5,$H43:$EJ43) -> 0.03
B44: Potential Rent | H44: ='Inputs & Drivers'!E50 -> 1480 | I44: =H44*(1+I43) -> 1480 | J44: =I44*(1+J43) -> 1480 | K44: =J44*(1+K43) -> 1480 | L44: =K44*(1+L43) -> 1480 | M44: =L44*(1+M43) -> 1480 | N44: =M44*(1+N43) -> 1480 | O44: =N44*(1+O43) -> 1480 | P44: =O44*(1+P43) -> 1480 | ... EJ44: =EI44*(1+EJ43) -> 1977.2134 | EL44: =SUMIF($H$6:$EJ$6,EL$6,$H44:$EJ44) -> 1480 | EM44: =SUMIF($H$6:$EJ$6,EM$6,$H44:$EJ44) -> 1480 | EN44: =SUMIF($H$6:$EJ$6,EN$6,$H44:$EJ44) -> 1509.8728 | EO44: =SUMIF($H$6:$EJ$6,EO$6,$H44:$EJ44) -> 1555.7971 | EP44: =SUMIF($H$6:$EJ$6,EP$6,$H44:$EJ44) -> 1603.1181 | EQ44: =SUMIF($H$6:$EJ$6,EQ$6,$H44:$EJ44) -> 1651.8785 | ER44: =SUMIF($H$6:$EJ$6,ER$6,$H44:$EJ44) -> 1702.122 | ES44: =SUMIF($H$6:$EJ$6,ES$6,$H44:$EJ44) -> 1753.8936 | ... EW44: =SUMIF($H$6:$EJ$6,EW$6,$H44:$EJ44) -> 1977.2134
B45: Concessions | H45: =-H44/12*('Inputs & Drivers'!$C$38)*(H$5<='Inputs & Drivers'!$J$42) -> -123.33333 | I45: =-I44/12*('Inputs & Drivers'!$C$38)*(I$5<='Inputs & Drivers'!$J$42) -> -123.33333 | J45: =-J44/12*('Inputs & Drivers'!$C$38)*(J$5<='Inputs & Drivers'!$J$42) -> -123.33333 | K45: =-K44/12*('Inputs & Drivers'!$C$38)*(K$5<='Inputs & Drivers'!$J$42) -> -123.33333 | L45: =-L44/12*('Inputs & Drivers'!$C$38)*(L$5<='Inputs & Drivers'!$J$42) -> -123.33333 | M45: =-M44/12*('Inputs & Drivers'!$C$38)*(M$5<='Inputs & Drivers'!$J$42) -> -123.33333 | N45: =-N44/12*('Inputs & Drivers'!$C$38)*(N$5<='Inputs & Drivers'!$J$42) -> -123.33333 | O45: =-O44/12*('Inputs & Drivers'!$C$38)*(O$5<='Inputs & Drivers'!$J$42) -> -123.33333 | ... EJ45: =-EJ44/12*('Inputs & Drivers'!$C$38)*(EJ$5<='Inputs & Drivers'!$J$42) -> 0 | EL45: =SUMIF($H$6:$EJ$6,EL$6,$H45:$EJ45) -> -123.33333 | EM45: =SUMIF($H$6:$EJ$6,EM$6,$H45:$EJ45) -> -123.33333 | EN45: =SUMIF($H$6:$EJ$6,EN$6,$H45:$EJ45) -> -125.82274 | EO45: =SUMIF($H$6:$EJ$6,EO$6,$H45:$EJ45) -> 0 | EP45: =SUMIF($H$6:$EJ$6,EP$6,$H45:$EJ45) -> 0 | EQ45: =SUMIF($H$6:$EJ$6,EQ$6,$H45:$EJ45) -> 0 | ER45: =SUMIF($H$6:$EJ$6,ER$6,$H45:$EJ45) -> 0 | ES45: =SUMIF($H$6:$EJ$6,ES$6,$H45:$EJ45) -> 0 | ... EW45: =SUMIF($H$6:$EJ$6,EW$6,$H45:$EJ45) -> 0
B46: Effective Rent | H46: =SUM(H44+H45) -> 1356.6667 | I46: =SUM(I44+I45) -> 1356.6667 | J46: =SUM(J44+J45) -> 1356.6667 | K46: =SUM(K44+K45) -> 1356.6667 | L46: =SUM(L44+L45) -> 1356.6667 | M46: =SUM(M44+M45) -> 1356.6667 | N46: =SUM(N44+N45) -> 1356.6667 | O46: =SUM(O44+O45) -> 1356.6667 | ... EJ46: =SUM(EJ44+EJ45) -> 1977.2134 | EL46: =SUM(EL44:EL45) -> 1356.6667 | EM46: =SUM(EM44:EM45) -> 1356.6667 | EN46: =SUM(EN44:EN45) -> 1384.0501 | EO46: =SUM(EO44:EO45) -> 1555.7971 | EP46: =SUM(EP44:EP45) -> 1603.1181 | EQ46: =SUM(EQ44:EQ45) -> 1651.8785 | ER46: =SUM(ER44:ER45) -> 1702.122 | ES46: =SUM(ES44:ES45) -> 1753.8936 | ... EW46: =SUM(EW44:EW45) -> 1977.2134
B48: INCOME
